package com.parzivail.test;

import java.util.Random;
import net.minecraft.block.Block;
import net.minecraft.init.Blocks;
import net.minecraft.world.World;
import net.minecraft.world.chunk.IChunkProvider;
import net.minecraft.world.gen.feature.WorldGenerator;
import cpw.mods.fml.common.IWorldGenerator;
import net.minecraft.nbt.NBTTagCompound;
import com.parzivail.pswm.StarWarsMod;

public class WorldGenEndorBase extends WorldGenerator implements IWorldGenerator
{
	public WorldGenEndorBase() { }

	@Override
	public void generate(Random random, int chunkX, int chunkZ, World world, IChunkProvider chunkGenerator, IChunkProvider chunkProvider) { }

	public void setBlock(World world, int x, int y, int z, Block block, int metadata)
	{
		world.setBlock(x, y, z, block, metadata, 2);
	}

	public boolean generate(World world, Random rand, int i, int j, int k)
	{
		this.setBlock(world, i + 0, j + 0, k + 0, Blocks.grass, 0);
		this.setBlock(world, i + 0, j + 0, k + 1, Blocks.grass, 0);
		this.setBlock(world, i + 0, j + 0, k + 2, Blocks.grass, 0);
		this.setBlock(world, i + 0, j + 0, k + 3, Blocks.grass, 0);
		this.setBlock(world, i + 0, j + 0, k + 4, Blocks.grass, 0);
		this.setBlock(world, i + 0, j + 0, k + 5, Blocks.grass, 0);
		this.setBlock(world, i + 0, j + 0, k + 6, Blocks.grass, 0);
		this.setBlock(world, i + 0, j + 0, k + 7, Blocks.grass, 0);
		this.setBlock(world, i + 0, j + 0, k + 8, Blocks.grass, 0);
		this.setBlock(world, i + 0, j + 0, k + 9, Blocks.grass, 0);
		this.setBlock(world, i + 0, j + 0, k + 10, Blocks.grass, 0);
		this.setBlock(world, i + 0, j + 0, k + 11, Blocks.grass, 0);
		this.setBlock(world, i + 0, j + 0, k + 12, Blocks.grass, 0);
		this.setBlock(world, i + 0, j + 0, k + 13, Blocks.grass, 0);
		this.setBlock(world, i + 0, j + 0, k + 14, Blocks.grass, 0);
		this.setBlock(world, i + 0, j + 0, k + 15, Blocks.grass, 0);
		this.setBlock(world, i + 0, j + 0, k + 16, Blocks.grass, 0);
		this.setBlock(world, i + 0, j + 0, k + 17, Blocks.grass, 0);
		this.setBlock(world, i + 0, j + 0, k + 18, Blocks.grass, 0);
		this.setBlock(world, i + 0, j + 0, k + 19, Blocks.grass, 0);
		this.setBlock(world, i + 0, j + 0, k + 20, Blocks.grass, 0);
		this.setBlock(world, i + 0, j + 0, k + 21, Blocks.grass, 0);
		this.setBlock(world, i + 0, j + 0, k + 22, Blocks.grass, 0);
		this.setBlock(world, i + 0, j + 0, k + 23, Blocks.grass, 0);
		this.setBlock(world, i + 0, j + 0, k + 24, Blocks.grass, 0);
		this.setBlock(world, i + 0, j + 0, k + 25, Blocks.grass, 0);
		this.setBlock(world, i + 0, j + 0, k + 26, Blocks.grass, 0);
		this.setBlock(world, i + 0, j + 0, k + 27, Blocks.grass, 0);
		this.setBlock(world, i + 0, j + 0, k + 28, Blocks.grass, 0);
		this.setBlock(world, i + 0, j + 0, k + 29, Blocks.grass, 0);
		this.setBlock(world, i + 0, j + 0, k + 30, Blocks.grass, 0);
		this.setBlock(world, i + 0, j + 0, k + 31, Blocks.grass, 0);
		this.setBlock(world, i + 0, j + 0, k + 32, Blocks.grass, 0);
		this.setBlock(world, i + 0, j + 0, k + 33, Blocks.grass, 0);
		this.setBlock(world, i + 0, j + 0, k + 34, Blocks.grass, 0);
		this.setBlock(world, i + 0, j + 1, k + 0, Blocks.air, 0);
		this.setBlock(world, i + 0, j + 1, k + 1, Blocks.air, 0);
		this.setBlock(world, i + 0, j + 1, k + 2, Blocks.air, 0);
		this.setBlock(world, i + 0, j + 1, k + 3, Blocks.air, 0);
		this.setBlock(world, i + 0, j + 1, k + 4, Blocks.air, 0);
		this.setBlock(world, i + 0, j + 1, k + 5, Blocks.air, 0);
		this.setBlock(world, i + 0, j + 1, k + 6, Blocks.air, 0);
		this.setBlock(world, i + 0, j + 1, k + 7, Blocks.air, 0);
		this.setBlock(world, i + 0, j + 1, k + 8, Blocks.air, 0);
		this.setBlock(world, i + 0, j + 1, k + 9, Blocks.air, 0);
		this.setBlock(world, i + 0, j + 1, k + 10, Blocks.air, 0);
		this.setBlock(world, i + 0, j + 1, k + 11, Blocks.air, 0);
		this.setBlock(world, i + 0, j + 1, k + 12, Blocks.air, 0);
		this.setBlock(world, i + 0, j + 1, k + 13, Blocks.air, 0);
		this.setBlock(world, i + 0, j + 1, k + 14, Blocks.air, 0);
		this.setBlock(world, i + 0, j + 1, k + 15, Blocks.air, 0);
		this.setBlock(world, i + 0, j + 1, k + 16, Blocks.air, 0);
		this.setBlock(world, i + 0, j + 1, k + 17, Blocks.air, 0);
		this.setBlock(world, i + 0, j + 1, k + 18, Blocks.air, 0);
		this.setBlock(world, i + 0, j + 1, k + 19, Blocks.air, 0);
		this.setBlock(world, i + 0, j + 1, k + 20, Blocks.air, 0);
		this.setBlock(world, i + 0, j + 1, k + 21, Blocks.air, 0);
		this.setBlock(world, i + 0, j + 1, k + 22, Blocks.air, 0);
		this.setBlock(world, i + 0, j + 1, k + 23, Blocks.air, 0);
		this.setBlock(world, i + 0, j + 1, k + 24, Blocks.air, 0);
		this.setBlock(world, i + 0, j + 1, k + 25, Blocks.air, 0);
		this.setBlock(world, i + 0, j + 1, k + 26, Blocks.air, 0);
		this.setBlock(world, i + 0, j + 1, k + 27, Blocks.air, 0);
		this.setBlock(world, i + 0, j + 1, k + 28, Blocks.air, 0);
		this.setBlock(world, i + 0, j + 1, k + 29, Blocks.air, 0);
		this.setBlock(world, i + 0, j + 1, k + 30, Blocks.air, 0);
		this.setBlock(world, i + 0, j + 1, k + 31, Blocks.air, 0);
		this.setBlock(world, i + 0, j + 1, k + 32, Blocks.air, 0);
		this.setBlock(world, i + 0, j + 1, k + 33, Blocks.air, 0);
		this.setBlock(world, i + 0, j + 1, k + 34, Blocks.air, 0);
		this.setBlock(world, i + 0, j + 2, k + 0, Blocks.air, 0);
		this.setBlock(world, i + 0, j + 2, k + 1, Blocks.air, 0);
		this.setBlock(world, i + 0, j + 2, k + 2, Blocks.air, 0);
		this.setBlock(world, i + 0, j + 2, k + 3, Blocks.air, 0);
		this.setBlock(world, i + 0, j + 2, k + 4, Blocks.air, 0);
		this.setBlock(world, i + 0, j + 2, k + 5, Blocks.air, 0);
		this.setBlock(world, i + 0, j + 2, k + 6, Blocks.air, 0);
		this.setBlock(world, i + 0, j + 2, k + 7, Blocks.air, 0);
		this.setBlock(world, i + 0, j + 2, k + 8, Blocks.air, 0);
		this.setBlock(world, i + 0, j + 2, k + 9, Blocks.air, 0);
		this.setBlock(world, i + 0, j + 2, k + 10, Blocks.air, 0);
		this.setBlock(world, i + 0, j + 2, k + 11, Blocks.air, 0);
		this.setBlock(world, i + 0, j + 2, k + 12, Blocks.air, 0);
		this.setBlock(world, i + 0, j + 2, k + 13, Blocks.air, 0);
		this.setBlock(world, i + 0, j + 2, k + 14, Blocks.air, 0);
		this.setBlock(world, i + 0, j + 2, k + 15, Blocks.air, 0);
		this.setBlock(world, i + 0, j + 2, k + 16, Blocks.air, 0);
		this.setBlock(world, i + 0, j + 2, k + 17, Blocks.air, 0);
		this.setBlock(world, i + 0, j + 2, k + 18, Blocks.air, 0);
		this.setBlock(world, i + 0, j + 2, k + 19, Blocks.air, 0);
		this.setBlock(world, i + 0, j + 2, k + 20, Blocks.air, 0);
		this.setBlock(world, i + 0, j + 2, k + 21, Blocks.air, 0);
		this.setBlock(world, i + 0, j + 2, k + 22, Blocks.air, 0);
		this.setBlock(world, i + 0, j + 2, k + 23, Blocks.air, 0);
		this.setBlock(world, i + 0, j + 2, k + 24, Blocks.air, 0);
		this.setBlock(world, i + 0, j + 2, k + 25, Blocks.air, 0);
		this.setBlock(world, i + 0, j + 2, k + 26, Blocks.air, 0);
		this.setBlock(world, i + 0, j + 2, k + 27, Blocks.air, 0);
		this.setBlock(world, i + 0, j + 2, k + 28, Blocks.air, 0);
		this.setBlock(world, i + 0, j + 2, k + 29, Blocks.air, 0);
		this.setBlock(world, i + 0, j + 2, k + 30, Blocks.air, 0);
		this.setBlock(world, i + 0, j + 2, k + 31, Blocks.air, 0);
		this.setBlock(world, i + 0, j + 2, k + 32, Blocks.air, 0);
		this.setBlock(world, i + 0, j + 2, k + 33, Blocks.air, 0);
		this.setBlock(world, i + 0, j + 2, k + 34, Blocks.air, 0);
		this.setBlock(world, i + 0, j + 3, k + 0, Blocks.air, 0);
		this.setBlock(world, i + 0, j + 3, k + 1, Blocks.air, 0);
		this.setBlock(world, i + 0, j + 3, k + 2, Blocks.air, 0);
		this.setBlock(world, i + 0, j + 3, k + 3, Blocks.air, 0);
		this.setBlock(world, i + 0, j + 3, k + 4, Blocks.air, 0);
		this.setBlock(world, i + 0, j + 3, k + 5, Blocks.air, 0);
		this.setBlock(world, i + 0, j + 3, k + 6, Blocks.air, 0);
		this.setBlock(world, i + 0, j + 3, k + 7, Blocks.air, 0);
		this.setBlock(world, i + 0, j + 3, k + 8, Blocks.air, 0);
		this.setBlock(world, i + 0, j + 3, k + 9, Blocks.air, 0);
		this.setBlock(world, i + 0, j + 3, k + 10, Blocks.air, 0);
		this.setBlock(world, i + 0, j + 3, k + 11, Blocks.air, 0);
		this.setBlock(world, i + 0, j + 3, k + 12, Blocks.air, 0);
		this.setBlock(world, i + 0, j + 3, k + 13, Blocks.air, 0);
		this.setBlock(world, i + 0, j + 3, k + 14, Blocks.air, 0);
		this.setBlock(world, i + 0, j + 3, k + 15, Blocks.air, 0);
		this.setBlock(world, i + 0, j + 3, k + 16, Blocks.air, 0);
		this.setBlock(world, i + 0, j + 3, k + 17, Blocks.air, 0);
		this.setBlock(world, i + 0, j + 3, k + 18, Blocks.air, 0);
		this.setBlock(world, i + 0, j + 3, k + 19, Blocks.air, 0);
		this.setBlock(world, i + 0, j + 3, k + 20, Blocks.air, 0);
		this.setBlock(world, i + 0, j + 3, k + 21, Blocks.air, 0);
		this.setBlock(world, i + 0, j + 3, k + 22, Blocks.air, 0);
		this.setBlock(world, i + 0, j + 3, k + 23, Blocks.air, 0);
		this.setBlock(world, i + 0, j + 3, k + 24, Blocks.air, 0);
		this.setBlock(world, i + 0, j + 3, k + 25, Blocks.air, 0);
		this.setBlock(world, i + 0, j + 3, k + 26, Blocks.air, 0);
		this.setBlock(world, i + 0, j + 3, k + 27, Blocks.air, 0);
		this.setBlock(world, i + 0, j + 3, k + 28, Blocks.air, 0);
		this.setBlock(world, i + 0, j + 3, k + 29, Blocks.air, 0);
		this.setBlock(world, i + 0, j + 3, k + 30, Blocks.air, 0);
		this.setBlock(world, i + 0, j + 3, k + 31, Blocks.air, 0);
		this.setBlock(world, i + 0, j + 3, k + 32, Blocks.air, 0);
		this.setBlock(world, i + 0, j + 3, k + 33, Blocks.air, 0);
		this.setBlock(world, i + 0, j + 3, k + 34, Blocks.air, 0);
		this.setBlock(world, i + 0, j + 4, k + 0, Blocks.air, 0);
		this.setBlock(world, i + 0, j + 4, k + 1, Blocks.air, 0);
		this.setBlock(world, i + 0, j + 4, k + 2, Blocks.air, 0);
		this.setBlock(world, i + 0, j + 4, k + 3, Blocks.air, 0);
		this.setBlock(world, i + 0, j + 4, k + 4, Blocks.air, 0);
		this.setBlock(world, i + 0, j + 4, k + 5, Blocks.air, 0);
		this.setBlock(world, i + 0, j + 4, k + 6, Blocks.air, 0);
		this.setBlock(world, i + 0, j + 4, k + 7, Blocks.air, 0);
		this.setBlock(world, i + 0, j + 4, k + 8, Blocks.air, 0);
		this.setBlock(world, i + 0, j + 4, k + 9, Blocks.air, 0);
		this.setBlock(world, i + 0, j + 4, k + 10, Blocks.air, 0);
		this.setBlock(world, i + 0, j + 4, k + 11, Blocks.air, 0);
		this.setBlock(world, i + 0, j + 4, k + 12, Blocks.air, 0);
		this.setBlock(world, i + 0, j + 4, k + 13, Blocks.air, 0);
		this.setBlock(world, i + 0, j + 4, k + 14, Blocks.air, 0);
		this.setBlock(world, i + 0, j + 4, k + 15, Blocks.air, 0);
		this.setBlock(world, i + 0, j + 4, k + 16, Blocks.air, 0);
		this.setBlock(world, i + 0, j + 4, k + 17, Blocks.air, 0);
		this.setBlock(world, i + 0, j + 4, k + 18, Blocks.air, 0);
		this.setBlock(world, i + 0, j + 4, k + 19, Blocks.air, 0);
		this.setBlock(world, i + 0, j + 4, k + 20, Blocks.air, 0);
		this.setBlock(world, i + 0, j + 4, k + 21, Blocks.air, 0);
		this.setBlock(world, i + 0, j + 4, k + 22, Blocks.air, 0);
		this.setBlock(world, i + 0, j + 4, k + 23, Blocks.air, 0);
		this.setBlock(world, i + 0, j + 4, k + 24, Blocks.air, 0);
		this.setBlock(world, i + 0, j + 4, k + 25, Blocks.air, 0);
		this.setBlock(world, i + 0, j + 4, k + 26, Blocks.air, 0);
		this.setBlock(world, i + 0, j + 4, k + 27, Blocks.air, 0);
		this.setBlock(world, i + 0, j + 4, k + 28, Blocks.air, 0);
		this.setBlock(world, i + 0, j + 4, k + 29, Blocks.air, 0);
		this.setBlock(world, i + 0, j + 4, k + 30, Blocks.air, 0);
		this.setBlock(world, i + 0, j + 4, k + 31, Blocks.air, 0);
		this.setBlock(world, i + 0, j + 4, k + 32, Blocks.air, 0);
		this.setBlock(world, i + 0, j + 4, k + 33, Blocks.air, 0);
		this.setBlock(world, i + 0, j + 4, k + 34, Blocks.air, 0);
		this.setBlock(world, i + 0, j + 5, k + 0, Blocks.air, 0);
		this.setBlock(world, i + 0, j + 5, k + 1, Blocks.air, 0);
		this.setBlock(world, i + 0, j + 5, k + 2, Blocks.air, 0);
		this.setBlock(world, i + 0, j + 5, k + 3, Blocks.air, 0);
		this.setBlock(world, i + 0, j + 5, k + 4, Blocks.air, 0);
		this.setBlock(world, i + 0, j + 5, k + 5, Blocks.air, 0);
		this.setBlock(world, i + 0, j + 5, k + 6, Blocks.planks, 0);
		world.setBlockMetadataWithNotify(i + 0, j + 5, k + 6, 5, 2);
		this.setBlock(world, i + 0, j + 5, k + 7, Blocks.planks, 0);
		world.setBlockMetadataWithNotify(i + 0, j + 5, k + 7, 5, 2);
		this.setBlock(world, i + 0, j + 5, k + 8, Blocks.planks, 0);
		world.setBlockMetadataWithNotify(i + 0, j + 5, k + 8, 5, 2);
		this.setBlock(world, i + 0, j + 5, k + 9, Blocks.planks, 0);
		world.setBlockMetadataWithNotify(i + 0, j + 5, k + 9, 5, 2);
		this.setBlock(world, i + 0, j + 5, k + 10, Blocks.planks, 0);
		world.setBlockMetadataWithNotify(i + 0, j + 5, k + 10, 5, 2);
		this.setBlock(world, i + 0, j + 5, k + 11, Blocks.planks, 0);
		world.setBlockMetadataWithNotify(i + 0, j + 5, k + 11, 5, 2);
		this.setBlock(world, i + 0, j + 5, k + 12, Blocks.planks, 0);
		world.setBlockMetadataWithNotify(i + 0, j + 5, k + 12, 5, 2);
		this.setBlock(world, i + 0, j + 5, k + 13, Blocks.planks, 0);
		world.setBlockMetadataWithNotify(i + 0, j + 5, k + 13, 5, 2);
		this.setBlock(world, i + 0, j + 5, k + 14, Blocks.planks, 0);
		world.setBlockMetadataWithNotify(i + 0, j + 5, k + 14, 5, 2);
		this.setBlock(world, i + 0, j + 5, k + 15, Blocks.planks, 0);
		world.setBlockMetadataWithNotify(i + 0, j + 5, k + 15, 5, 2);
		this.setBlock(world, i + 0, j + 5, k + 16, Blocks.planks, 0);
		world.setBlockMetadataWithNotify(i + 0, j + 5, k + 16, 5, 2);
		this.setBlock(world, i + 0, j + 5, k + 17, Blocks.planks, 0);
		world.setBlockMetadataWithNotify(i + 0, j + 5, k + 17, 5, 2);
		this.setBlock(world, i + 0, j + 5, k + 18, Blocks.planks, 0);
		world.setBlockMetadataWithNotify(i + 0, j + 5, k + 18, 5, 2);
		this.setBlock(world, i + 0, j + 5, k + 19, Blocks.planks, 0);
		world.setBlockMetadataWithNotify(i + 0, j + 5, k + 19, 5, 2);
		this.setBlock(world, i + 0, j + 5, k + 20, Blocks.planks, 0);
		world.setBlockMetadataWithNotify(i + 0, j + 5, k + 20, 5, 2);
		this.setBlock(world, i + 0, j + 5, k + 21, Blocks.planks, 0);
		world.setBlockMetadataWithNotify(i + 0, j + 5, k + 21, 5, 2);
		this.setBlock(world, i + 0, j + 5, k + 22, Blocks.planks, 0);
		world.setBlockMetadataWithNotify(i + 0, j + 5, k + 22, 5, 2);
		this.setBlock(world, i + 0, j + 5, k + 23, Blocks.planks, 0);
		world.setBlockMetadataWithNotify(i + 0, j + 5, k + 23, 5, 2);
		this.setBlock(world, i + 0, j + 5, k + 24, Blocks.planks, 0);
		world.setBlockMetadataWithNotify(i + 0, j + 5, k + 24, 5, 2);
		this.setBlock(world, i + 0, j + 5, k + 25, Blocks.planks, 0);
		world.setBlockMetadataWithNotify(i + 0, j + 5, k + 25, 5, 2);
		this.setBlock(world, i + 0, j + 5, k + 26, Blocks.planks, 0);
		world.setBlockMetadataWithNotify(i + 0, j + 5, k + 26, 5, 2);
		this.setBlock(world, i + 0, j + 5, k + 27, Blocks.planks, 0);
		world.setBlockMetadataWithNotify(i + 0, j + 5, k + 27, 5, 2);
		this.setBlock(world, i + 0, j + 5, k + 28, Blocks.planks, 0);
		world.setBlockMetadataWithNotify(i + 0, j + 5, k + 28, 5, 2);
		this.setBlock(world, i + 0, j + 5, k + 29, Blocks.air, 0);
		this.setBlock(world, i + 0, j + 5, k + 30, Blocks.air, 0);
		this.setBlock(world, i + 0, j + 5, k + 31, Blocks.air, 0);
		this.setBlock(world, i + 0, j + 5, k + 32, Blocks.air, 0);
		this.setBlock(world, i + 0, j + 5, k + 33, Blocks.air, 0);
		this.setBlock(world, i + 0, j + 5, k + 34, Blocks.air, 0);
		this.setBlock(world, i + 0, j + 6, k + 0, Blocks.air, 0);
		this.setBlock(world, i + 0, j + 6, k + 1, Blocks.air, 0);
		this.setBlock(world, i + 0, j + 6, k + 2, Blocks.air, 0);
		this.setBlock(world, i + 0, j + 6, k + 3, Blocks.air, 0);
		this.setBlock(world, i + 0, j + 6, k + 4, Blocks.air, 0);
		this.setBlock(world, i + 0, j + 6, k + 5, Blocks.air, 0);
		this.setBlock(world, i + 0, j + 6, k + 6, Blocks.air, 0);
		this.setBlock(world, i + 0, j + 6, k + 7, Blocks.air, 0);
		this.setBlock(world, i + 0, j + 6, k + 8, Blocks.air, 0);
		this.setBlock(world, i + 0, j + 6, k + 9, Blocks.air, 0);
		this.setBlock(world, i + 0, j + 6, k + 10, Blocks.air, 0);
		this.setBlock(world, i + 0, j + 6, k + 11, Blocks.air, 0);
		this.setBlock(world, i + 0, j + 6, k + 12, Blocks.air, 0);
		this.setBlock(world, i + 0, j + 6, k + 13, Blocks.air, 0);
		this.setBlock(world, i + 0, j + 6, k + 14, Blocks.air, 0);
		this.setBlock(world, i + 0, j + 6, k + 15, Blocks.air, 0);
		this.setBlock(world, i + 0, j + 6, k + 16, Blocks.air, 0);
		this.setBlock(world, i + 0, j + 6, k + 17, Blocks.air, 0);
		this.setBlock(world, i + 0, j + 6, k + 18, Blocks.air, 0);
		this.setBlock(world, i + 0, j + 6, k + 19, Blocks.air, 0);
		this.setBlock(world, i + 0, j + 6, k + 20, Blocks.air, 0);
		this.setBlock(world, i + 0, j + 6, k + 21, Blocks.air, 0);
		this.setBlock(world, i + 0, j + 6, k + 22, Blocks.air, 0);
		this.setBlock(world, i + 0, j + 6, k + 23, Blocks.air, 0);
		this.setBlock(world, i + 0, j + 6, k + 24, Blocks.air, 0);
		this.setBlock(world, i + 0, j + 6, k + 25, Blocks.air, 0);
		this.setBlock(world, i + 0, j + 6, k + 26, Blocks.air, 0);
		this.setBlock(world, i + 0, j + 6, k + 27, Blocks.air, 0);
		this.setBlock(world, i + 0, j + 6, k + 28, Blocks.air, 0);
		this.setBlock(world, i + 0, j + 6, k + 29, Blocks.air, 0);
		this.setBlock(world, i + 0, j + 6, k + 30, Blocks.air, 0);
		this.setBlock(world, i + 0, j + 6, k + 31, Blocks.air, 0);
		this.setBlock(world, i + 0, j + 6, k + 32, Blocks.air, 0);
		this.setBlock(world, i + 0, j + 6, k + 33, Blocks.air, 0);
		this.setBlock(world, i + 0, j + 6, k + 34, Blocks.air, 0);
		this.setBlock(world, i + 0, j + 7, k + 0, Blocks.air, 0);
		this.setBlock(world, i + 0, j + 7, k + 1, Blocks.air, 0);
		this.setBlock(world, i + 0, j + 7, k + 2, Blocks.air, 0);
		this.setBlock(world, i + 0, j + 7, k + 3, Blocks.air, 0);
		this.setBlock(world, i + 0, j + 7, k + 4, Blocks.air, 0);
		this.setBlock(world, i + 0, j + 7, k + 5, Blocks.air, 0);
		this.setBlock(world, i + 0, j + 7, k + 6, Blocks.air, 0);
		this.setBlock(world, i + 0, j + 7, k + 7, Blocks.air, 0);
		this.setBlock(world, i + 0, j + 7, k + 8, Blocks.air, 0);
		this.setBlock(world, i + 0, j + 7, k + 9, Blocks.air, 0);
		this.setBlock(world, i + 0, j + 7, k + 10, Blocks.air, 0);
		this.setBlock(world, i + 0, j + 7, k + 11, Blocks.air, 0);
		this.setBlock(world, i + 0, j + 7, k + 12, Blocks.air, 0);
		this.setBlock(world, i + 0, j + 7, k + 13, Blocks.air, 0);
		this.setBlock(world, i + 0, j + 7, k + 14, Blocks.air, 0);
		this.setBlock(world, i + 0, j + 7, k + 15, Blocks.air, 0);
		this.setBlock(world, i + 0, j + 7, k + 16, Blocks.air, 0);
		this.setBlock(world, i + 0, j + 7, k + 17, Blocks.air, 0);
		this.setBlock(world, i + 0, j + 7, k + 18, Blocks.air, 0);
		this.setBlock(world, i + 0, j + 7, k + 19, Blocks.air, 0);
		this.setBlock(world, i + 0, j + 7, k + 20, Blocks.air, 0);
		this.setBlock(world, i + 0, j + 7, k + 21, Blocks.air, 0);
		this.setBlock(world, i + 0, j + 7, k + 22, Blocks.air, 0);
		this.setBlock(world, i + 0, j + 7, k + 23, Blocks.air, 0);
		this.setBlock(world, i + 0, j + 7, k + 24, Blocks.air, 0);
		this.setBlock(world, i + 0, j + 7, k + 25, Blocks.air, 0);
		this.setBlock(world, i + 0, j + 7, k + 26, Blocks.air, 0);
		this.setBlock(world, i + 0, j + 7, k + 27, Blocks.air, 0);
		this.setBlock(world, i + 0, j + 7, k + 28, Blocks.air, 0);
		this.setBlock(world, i + 0, j + 7, k + 29, Blocks.air, 0);
		this.setBlock(world, i + 0, j + 7, k + 30, Blocks.air, 0);
		this.setBlock(world, i + 0, j + 7, k + 31, Blocks.air, 0);
		this.setBlock(world, i + 0, j + 7, k + 32, Blocks.air, 0);
		this.setBlock(world, i + 0, j + 7, k + 33, Blocks.air, 0);
		this.setBlock(world, i + 0, j + 7, k + 34, Blocks.air, 0);
		this.setBlock(world, i + 1, j + 0, k + 0, Blocks.grass, 0);
		this.setBlock(world, i + 1, j + 0, k + 1, Blocks.grass, 0);
		this.setBlock(world, i + 1, j + 0, k + 2, Blocks.grass, 0);
		this.setBlock(world, i + 1, j + 0, k + 3, Blocks.grass, 0);
		this.setBlock(world, i + 1, j + 0, k + 4, Blocks.grass, 0);
		this.setBlock(world, i + 1, j + 0, k + 5, Blocks.grass, 0);
		this.setBlock(world, i + 1, j + 0, k + 6, Blocks.grass, 0);
		this.setBlock(world, i + 1, j + 0, k + 7, Blocks.grass, 0);
		this.setBlock(world, i + 1, j + 0, k + 8, Blocks.grass, 0);
		this.setBlock(world, i + 1, j + 0, k + 9, Blocks.grass, 0);
		this.setBlock(world, i + 1, j + 0, k + 10, Blocks.grass, 0);
		this.setBlock(world, i + 1, j + 0, k + 11, Blocks.grass, 0);
		this.setBlock(world, i + 1, j + 0, k + 12, Blocks.grass, 0);
		this.setBlock(world, i + 1, j + 0, k + 13, Blocks.grass, 0);
		this.setBlock(world, i + 1, j + 0, k + 14, Blocks.grass, 0);
		this.setBlock(world, i + 1, j + 0, k + 15, Blocks.grass, 0);
		this.setBlock(world, i + 1, j + 0, k + 16, Blocks.grass, 0);
		this.setBlock(world, i + 1, j + 0, k + 17, Blocks.grass, 0);
		this.setBlock(world, i + 1, j + 0, k + 18, Blocks.grass, 0);
		this.setBlock(world, i + 1, j + 0, k + 19, Blocks.grass, 0);
		this.setBlock(world, i + 1, j + 0, k + 20, Blocks.grass, 0);
		this.setBlock(world, i + 1, j + 0, k + 21, Blocks.grass, 0);
		this.setBlock(world, i + 1, j + 0, k + 22, Blocks.grass, 0);
		this.setBlock(world, i + 1, j + 0, k + 23, Blocks.grass, 0);
		this.setBlock(world, i + 1, j + 0, k + 24, Blocks.grass, 0);
		this.setBlock(world, i + 1, j + 0, k + 25, Blocks.grass, 0);
		this.setBlock(world, i + 1, j + 0, k + 26, Blocks.grass, 0);
		this.setBlock(world, i + 1, j + 0, k + 27, Blocks.grass, 0);
		this.setBlock(world, i + 1, j + 0, k + 28, Blocks.grass, 0);
		this.setBlock(world, i + 1, j + 0, k + 29, Blocks.grass, 0);
		this.setBlock(world, i + 1, j + 0, k + 30, Blocks.grass, 0);
		this.setBlock(world, i + 1, j + 0, k + 31, Blocks.grass, 0);
		this.setBlock(world, i + 1, j + 0, k + 32, Blocks.grass, 0);
		this.setBlock(world, i + 1, j + 0, k + 33, Blocks.grass, 0);
		this.setBlock(world, i + 1, j + 0, k + 34, Blocks.grass, 0);
		this.setBlock(world, i + 1, j + 1, k + 0, Blocks.air, 0);
		this.setBlock(world, i + 1, j + 1, k + 1, Blocks.air, 0);
		this.setBlock(world, i + 1, j + 1, k + 2, Blocks.air, 0);
		this.setBlock(world, i + 1, j + 1, k + 3, Blocks.air, 0);
		this.setBlock(world, i + 1, j + 1, k + 4, Blocks.air, 0);
		this.setBlock(world, i + 1, j + 1, k + 5, Blocks.air, 0);
		this.setBlock(world, i + 1, j + 1, k + 6, Blocks.air, 0);
		this.setBlock(world, i + 1, j + 1, k + 7, Blocks.planks, 0);
		world.setBlockMetadataWithNotify(i + 1, j + 1, k + 7, 5, 2);
		this.setBlock(world, i + 1, j + 1, k + 8, Blocks.planks, 0);
		world.setBlockMetadataWithNotify(i + 1, j + 1, k + 8, 5, 2);
		this.setBlock(world, i + 1, j + 1, k + 9, Blocks.planks, 0);
		world.setBlockMetadataWithNotify(i + 1, j + 1, k + 9, 5, 2);
		this.setBlock(world, i + 1, j + 1, k + 10, Blocks.planks, 0);
		world.setBlockMetadataWithNotify(i + 1, j + 1, k + 10, 5, 2);
		this.setBlock(world, i + 1, j + 1, k + 11, Blocks.planks, 0);
		world.setBlockMetadataWithNotify(i + 1, j + 1, k + 11, 5, 2);
		this.setBlock(world, i + 1, j + 1, k + 12, Blocks.planks, 0);
		world.setBlockMetadataWithNotify(i + 1, j + 1, k + 12, 5, 2);
		this.setBlock(world, i + 1, j + 1, k + 13, Blocks.planks, 0);
		world.setBlockMetadataWithNotify(i + 1, j + 1, k + 13, 5, 2);
		this.setBlock(world, i + 1, j + 1, k + 14, Blocks.planks, 0);
		world.setBlockMetadataWithNotify(i + 1, j + 1, k + 14, 5, 2);
		this.setBlock(world, i + 1, j + 1, k + 15, Blocks.planks, 0);
		world.setBlockMetadataWithNotify(i + 1, j + 1, k + 15, 5, 2);
		this.setBlock(world, i + 1, j + 1, k + 16, Blocks.planks, 0);
		world.setBlockMetadataWithNotify(i + 1, j + 1, k + 16, 5, 2);
		this.setBlock(world, i + 1, j + 1, k + 17, Blocks.planks, 0);
		world.setBlockMetadataWithNotify(i + 1, j + 1, k + 17, 5, 2);
		this.setBlock(world, i + 1, j + 1, k + 18, Blocks.planks, 0);
		world.setBlockMetadataWithNotify(i + 1, j + 1, k + 18, 5, 2);
		this.setBlock(world, i + 1, j + 1, k + 19, Blocks.planks, 0);
		world.setBlockMetadataWithNotify(i + 1, j + 1, k + 19, 5, 2);
		this.setBlock(world, i + 1, j + 1, k + 20, Blocks.planks, 0);
		world.setBlockMetadataWithNotify(i + 1, j + 1, k + 20, 5, 2);
		this.setBlock(world, i + 1, j + 1, k + 21, Blocks.planks, 0);
		world.setBlockMetadataWithNotify(i + 1, j + 1, k + 21, 5, 2);
		this.setBlock(world, i + 1, j + 1, k + 22, Blocks.planks, 0);
		world.setBlockMetadataWithNotify(i + 1, j + 1, k + 22, 5, 2);
		this.setBlock(world, i + 1, j + 1, k + 23, Blocks.planks, 0);
		world.setBlockMetadataWithNotify(i + 1, j + 1, k + 23, 5, 2);
		this.setBlock(world, i + 1, j + 1, k + 24, Blocks.planks, 0);
		world.setBlockMetadataWithNotify(i + 1, j + 1, k + 24, 5, 2);
		this.setBlock(world, i + 1, j + 1, k + 25, Blocks.planks, 0);
		world.setBlockMetadataWithNotify(i + 1, j + 1, k + 25, 5, 2);
		this.setBlock(world, i + 1, j + 1, k + 26, Blocks.planks, 0);
		world.setBlockMetadataWithNotify(i + 1, j + 1, k + 26, 5, 2);
		this.setBlock(world, i + 1, j + 1, k + 27, Blocks.planks, 0);
		world.setBlockMetadataWithNotify(i + 1, j + 1, k + 27, 5, 2);
		this.setBlock(world, i + 1, j + 1, k + 28, Blocks.air, 0);
		this.setBlock(world, i + 1, j + 1, k + 29, Blocks.air, 0);
		this.setBlock(world, i + 1, j + 1, k + 30, Blocks.air, 0);
		this.setBlock(world, i + 1, j + 1, k + 31, Blocks.air, 0);
		this.setBlock(world, i + 1, j + 1, k + 32, Blocks.air, 0);
		this.setBlock(world, i + 1, j + 1, k + 33, Blocks.air, 0);
		this.setBlock(world, i + 1, j + 1, k + 34, Blocks.air, 0);
		this.setBlock(world, i + 1, j + 2, k + 0, Blocks.air, 0);
		this.setBlock(world, i + 1, j + 2, k + 1, Blocks.air, 0);
		this.setBlock(world, i + 1, j + 2, k + 2, Blocks.air, 0);
		this.setBlock(world, i + 1, j + 2, k + 3, Blocks.air, 0);
		this.setBlock(world, i + 1, j + 2, k + 4, Blocks.air, 0);
		this.setBlock(world, i + 1, j + 2, k + 5, Blocks.air, 0);
		this.setBlock(world, i + 1, j + 2, k + 6, Blocks.air, 0);
		this.setBlock(world, i + 1, j + 2, k + 7, Blocks.air, 0);
		this.setBlock(world, i + 1, j + 2, k + 8, Blocks.air, 0);
		this.setBlock(world, i + 1, j + 2, k + 9, Blocks.planks, 0);
		world.setBlockMetadataWithNotify(i + 1, j + 2, k + 9, 5, 2);
		this.setBlock(world, i + 1, j + 2, k + 10, Blocks.planks, 0);
		world.setBlockMetadataWithNotify(i + 1, j + 2, k + 10, 5, 2);
		this.setBlock(world, i + 1, j + 2, k + 11, Blocks.planks, 0);
		world.setBlockMetadataWithNotify(i + 1, j + 2, k + 11, 5, 2);
		this.setBlock(world, i + 1, j + 2, k + 12, Blocks.planks, 0);
		world.setBlockMetadataWithNotify(i + 1, j + 2, k + 12, 5, 2);
		this.setBlock(world, i + 1, j + 2, k + 13, Blocks.planks, 0);
		world.setBlockMetadataWithNotify(i + 1, j + 2, k + 13, 5, 2);
		this.setBlock(world, i + 1, j + 2, k + 14, Blocks.planks, 0);
		world.setBlockMetadataWithNotify(i + 1, j + 2, k + 14, 5, 2);
		this.setBlock(world, i + 1, j + 2, k + 15, Blocks.planks, 0);
		world.setBlockMetadataWithNotify(i + 1, j + 2, k + 15, 5, 2);
		this.setBlock(world, i + 1, j + 2, k + 16, Blocks.planks, 0);
		world.setBlockMetadataWithNotify(i + 1, j + 2, k + 16, 5, 2);
		this.setBlock(world, i + 1, j + 2, k + 17, Blocks.planks, 0);
		world.setBlockMetadataWithNotify(i + 1, j + 2, k + 17, 5, 2);
		this.setBlock(world, i + 1, j + 2, k + 18, Blocks.planks, 0);
		world.setBlockMetadataWithNotify(i + 1, j + 2, k + 18, 5, 2);
		this.setBlock(world, i + 1, j + 2, k + 19, Blocks.planks, 0);
		world.setBlockMetadataWithNotify(i + 1, j + 2, k + 19, 5, 2);
		this.setBlock(world, i + 1, j + 2, k + 20, Blocks.planks, 0);
		world.setBlockMetadataWithNotify(i + 1, j + 2, k + 20, 5, 2);
		this.setBlock(world, i + 1, j + 2, k + 21, Blocks.planks, 0);
		world.setBlockMetadataWithNotify(i + 1, j + 2, k + 21, 5, 2);
		this.setBlock(world, i + 1, j + 2, k + 22, Blocks.planks, 0);
		world.setBlockMetadataWithNotify(i + 1, j + 2, k + 22, 5, 2);
		this.setBlock(world, i + 1, j + 2, k + 23, Blocks.planks, 0);
		world.setBlockMetadataWithNotify(i + 1, j + 2, k + 23, 5, 2);
		this.setBlock(world, i + 1, j + 2, k + 24, Blocks.planks, 0);
		world.setBlockMetadataWithNotify(i + 1, j + 2, k + 24, 5, 2);
		this.setBlock(world, i + 1, j + 2, k + 25, Blocks.planks, 0);
		world.setBlockMetadataWithNotify(i + 1, j + 2, k + 25, 5, 2);
		this.setBlock(world, i + 1, j + 2, k + 26, Blocks.air, 0);
		this.setBlock(world, i + 1, j + 2, k + 27, Blocks.air, 0);
		this.setBlock(world, i + 1, j + 2, k + 28, Blocks.air, 0);
		this.setBlock(world, i + 1, j + 2, k + 29, Blocks.air, 0);
		this.setBlock(world, i + 1, j + 2, k + 30, Blocks.air, 0);
		this.setBlock(world, i + 1, j + 2, k + 31, Blocks.air, 0);
		this.setBlock(world, i + 1, j + 2, k + 32, Blocks.air, 0);
		this.setBlock(world, i + 1, j + 2, k + 33, Blocks.air, 0);
		this.setBlock(world, i + 1, j + 2, k + 34, Blocks.air, 0);
		this.setBlock(world, i + 1, j + 3, k + 0, Blocks.air, 0);
		this.setBlock(world, i + 1, j + 3, k + 1, Blocks.air, 0);
		this.setBlock(world, i + 1, j + 3, k + 2, Blocks.air, 0);
		this.setBlock(world, i + 1, j + 3, k + 3, Blocks.air, 0);
		this.setBlock(world, i + 1, j + 3, k + 4, Blocks.air, 0);
		this.setBlock(world, i + 1, j + 3, k + 5, Blocks.air, 0);
		this.setBlock(world, i + 1, j + 3, k + 6, Blocks.air, 0);
		this.setBlock(world, i + 1, j + 3, k + 7, Blocks.air, 0);
		this.setBlock(world, i + 1, j + 3, k + 8, Blocks.air, 0);
		this.setBlock(world, i + 1, j + 3, k + 9, Blocks.air, 0);
		this.setBlock(world, i + 1, j + 3, k + 10, Blocks.air, 0);
		this.setBlock(world, i + 1, j + 3, k + 11, Blocks.planks, 0);
		world.setBlockMetadataWithNotify(i + 1, j + 3, k + 11, 5, 2);
		this.setBlock(world, i + 1, j + 3, k + 12, Blocks.planks, 0);
		world.setBlockMetadataWithNotify(i + 1, j + 3, k + 12, 5, 2);
		this.setBlock(world, i + 1, j + 3, k + 13, Blocks.planks, 0);
		world.setBlockMetadataWithNotify(i + 1, j + 3, k + 13, 5, 2);
		this.setBlock(world, i + 1, j + 3, k + 14, Blocks.planks, 0);
		world.setBlockMetadataWithNotify(i + 1, j + 3, k + 14, 5, 2);
		this.setBlock(world, i + 1, j + 3, k + 15, Blocks.planks, 0);
		world.setBlockMetadataWithNotify(i + 1, j + 3, k + 15, 5, 2);
		this.setBlock(world, i + 1, j + 3, k + 16, Blocks.planks, 0);
		world.setBlockMetadataWithNotify(i + 1, j + 3, k + 16, 5, 2);
		this.setBlock(world, i + 1, j + 3, k + 17, Blocks.planks, 0);
		world.setBlockMetadataWithNotify(i + 1, j + 3, k + 17, 5, 2);
		this.setBlock(world, i + 1, j + 3, k + 18, Blocks.planks, 0);
		world.setBlockMetadataWithNotify(i + 1, j + 3, k + 18, 5, 2);
		this.setBlock(world, i + 1, j + 3, k + 19, Blocks.planks, 0);
		world.setBlockMetadataWithNotify(i + 1, j + 3, k + 19, 5, 2);
		this.setBlock(world, i + 1, j + 3, k + 20, Blocks.planks, 0);
		world.setBlockMetadataWithNotify(i + 1, j + 3, k + 20, 5, 2);
		this.setBlock(world, i + 1, j + 3, k + 21, Blocks.planks, 0);
		world.setBlockMetadataWithNotify(i + 1, j + 3, k + 21, 5, 2);
		this.setBlock(world, i + 1, j + 3, k + 22, Blocks.planks, 0);
		world.setBlockMetadataWithNotify(i + 1, j + 3, k + 22, 5, 2);
		this.setBlock(world, i + 1, j + 3, k + 23, Blocks.planks, 0);
		world.setBlockMetadataWithNotify(i + 1, j + 3, k + 23, 5, 2);
		this.setBlock(world, i + 1, j + 3, k + 24, Blocks.air, 0);
		this.setBlock(world, i + 1, j + 3, k + 25, Blocks.air, 0);
		this.setBlock(world, i + 1, j + 3, k + 26, Blocks.air, 0);
		this.setBlock(world, i + 1, j + 3, k + 27, Blocks.air, 0);
		this.setBlock(world, i + 1, j + 3, k + 28, Blocks.air, 0);
		this.setBlock(world, i + 1, j + 3, k + 29, Blocks.air, 0);
		this.setBlock(world, i + 1, j + 3, k + 30, Blocks.air, 0);
		this.setBlock(world, i + 1, j + 3, k + 31, Blocks.air, 0);
		this.setBlock(world, i + 1, j + 3, k + 32, Blocks.air, 0);
		this.setBlock(world, i + 1, j + 3, k + 33, Blocks.air, 0);
		this.setBlock(world, i + 1, j + 3, k + 34, Blocks.air, 0);
		this.setBlock(world, i + 1, j + 4, k + 0, Blocks.air, 0);
		this.setBlock(world, i + 1, j + 4, k + 1, Blocks.air, 0);
		this.setBlock(world, i + 1, j + 4, k + 2, Blocks.air, 0);
		this.setBlock(world, i + 1, j + 4, k + 3, Blocks.air, 0);
		this.setBlock(world, i + 1, j + 4, k + 4, Blocks.air, 0);
		this.setBlock(world, i + 1, j + 4, k + 5, Blocks.air, 0);
		this.setBlock(world, i + 1, j + 4, k + 6, Blocks.air, 0);
		this.setBlock(world, i + 1, j + 4, k + 7, Blocks.air, 0);
		this.setBlock(world, i + 1, j + 4, k + 8, Blocks.air, 0);
		this.setBlock(world, i + 1, j + 4, k + 9, Blocks.air, 0);
		this.setBlock(world, i + 1, j + 4, k + 10, Blocks.air, 0);
		this.setBlock(world, i + 1, j + 4, k + 11, Blocks.planks, 0);
		world.setBlockMetadataWithNotify(i + 1, j + 4, k + 11, 5, 2);
		this.setBlock(world, i + 1, j + 4, k + 12, Blocks.planks, 0);
		world.setBlockMetadataWithNotify(i + 1, j + 4, k + 12, 5, 2);
		this.setBlock(world, i + 1, j + 4, k + 13, Blocks.planks, 0);
		world.setBlockMetadataWithNotify(i + 1, j + 4, k + 13, 5, 2);
		this.setBlock(world, i + 1, j + 4, k + 14, Blocks.planks, 0);
		world.setBlockMetadataWithNotify(i + 1, j + 4, k + 14, 5, 2);
		this.setBlock(world, i + 1, j + 4, k + 15, Blocks.planks, 0);
		world.setBlockMetadataWithNotify(i + 1, j + 4, k + 15, 5, 2);
		this.setBlock(world, i + 1, j + 4, k + 16, Blocks.planks, 0);
		world.setBlockMetadataWithNotify(i + 1, j + 4, k + 16, 5, 2);
		this.setBlock(world, i + 1, j + 4, k + 17, Blocks.planks, 0);
		world.setBlockMetadataWithNotify(i + 1, j + 4, k + 17, 5, 2);
		this.setBlock(world, i + 1, j + 4, k + 18, Blocks.planks, 0);
		world.setBlockMetadataWithNotify(i + 1, j + 4, k + 18, 5, 2);
		this.setBlock(world, i + 1, j + 4, k + 19, Blocks.planks, 0);
		world.setBlockMetadataWithNotify(i + 1, j + 4, k + 19, 5, 2);
		this.setBlock(world, i + 1, j + 4, k + 20, Blocks.planks, 0);
		world.setBlockMetadataWithNotify(i + 1, j + 4, k + 20, 5, 2);
		this.setBlock(world, i + 1, j + 4, k + 21, Blocks.planks, 0);
		world.setBlockMetadataWithNotify(i + 1, j + 4, k + 21, 5, 2);
		this.setBlock(world, i + 1, j + 4, k + 22, Blocks.planks, 0);
		world.setBlockMetadataWithNotify(i + 1, j + 4, k + 22, 5, 2);
		this.setBlock(world, i + 1, j + 4, k + 23, Blocks.planks, 0);
		world.setBlockMetadataWithNotify(i + 1, j + 4, k + 23, 5, 2);
		this.setBlock(world, i + 1, j + 4, k + 24, Blocks.air, 0);
		this.setBlock(world, i + 1, j + 4, k + 25, Blocks.air, 0);
		this.setBlock(world, i + 1, j + 4, k + 26, Blocks.air, 0);
		this.setBlock(world, i + 1, j + 4, k + 27, Blocks.air, 0);
		this.setBlock(world, i + 1, j + 4, k + 28, Blocks.air, 0);
		this.setBlock(world, i + 1, j + 4, k + 29, Blocks.air, 0);
		this.setBlock(world, i + 1, j + 4, k + 30, Blocks.air, 0);
		this.setBlock(world, i + 1, j + 4, k + 31, Blocks.air, 0);
		this.setBlock(world, i + 1, j + 4, k + 32, Blocks.air, 0);
		this.setBlock(world, i + 1, j + 4, k + 33, Blocks.air, 0);
		this.setBlock(world, i + 1, j + 4, k + 34, Blocks.air, 0);
		this.setBlock(world, i + 1, j + 5, k + 0, Blocks.air, 0);
		this.setBlock(world, i + 1, j + 5, k + 1, Blocks.air, 0);
		this.setBlock(world, i + 1, j + 5, k + 2, Blocks.air, 0);
		this.setBlock(world, i + 1, j + 5, k + 3, Blocks.air, 0);
		this.setBlock(world, i + 1, j + 5, k + 4, Blocks.planks, 0);
		world.setBlockMetadataWithNotify(i + 1, j + 5, k + 4, 5, 2);
		this.setBlock(world, i + 1, j + 5, k + 5, Blocks.planks, 0);
		world.setBlockMetadataWithNotify(i + 1, j + 5, k + 5, 5, 2);
		this.setBlock(world, i + 1, j + 5, k + 6, Blocks.planks, 0);
		world.setBlockMetadataWithNotify(i + 1, j + 5, k + 6, 5, 2);
		this.setBlock(world, i + 1, j + 5, k + 7, Blocks.planks, 0);
		world.setBlockMetadataWithNotify(i + 1, j + 5, k + 7, 5, 2);
		this.setBlock(world, i + 1, j + 5, k + 8, Blocks.planks, 0);
		world.setBlockMetadataWithNotify(i + 1, j + 5, k + 8, 5, 2);
		this.setBlock(world, i + 1, j + 5, k + 9, Blocks.planks, 0);
		world.setBlockMetadataWithNotify(i + 1, j + 5, k + 9, 5, 2);
		this.setBlock(world, i + 1, j + 5, k + 10, Blocks.planks, 0);
		world.setBlockMetadataWithNotify(i + 1, j + 5, k + 10, 5, 2);
		this.setBlock(world, i + 1, j + 5, k + 11, Blocks.planks, 0);
		world.setBlockMetadataWithNotify(i + 1, j + 5, k + 11, 5, 2);
		this.setBlock(world, i + 1, j + 5, k + 12, Blocks.planks, 0);
		world.setBlockMetadataWithNotify(i + 1, j + 5, k + 12, 5, 2);
		this.setBlock(world, i + 1, j + 5, k + 13, Blocks.planks, 0);
		world.setBlockMetadataWithNotify(i + 1, j + 5, k + 13, 5, 2);
		this.setBlock(world, i + 1, j + 5, k + 14, Blocks.planks, 0);
		world.setBlockMetadataWithNotify(i + 1, j + 5, k + 14, 5, 2);
		this.setBlock(world, i + 1, j + 5, k + 15, Blocks.planks, 0);
		world.setBlockMetadataWithNotify(i + 1, j + 5, k + 15, 5, 2);
		this.setBlock(world, i + 1, j + 5, k + 16, Blocks.planks, 0);
		world.setBlockMetadataWithNotify(i + 1, j + 5, k + 16, 5, 2);
		this.setBlock(world, i + 1, j + 5, k + 17, Blocks.planks, 0);
		world.setBlockMetadataWithNotify(i + 1, j + 5, k + 17, 5, 2);
		this.setBlock(world, i + 1, j + 5, k + 18, Blocks.planks, 0);
		world.setBlockMetadataWithNotify(i + 1, j + 5, k + 18, 5, 2);
		this.setBlock(world, i + 1, j + 5, k + 19, Blocks.planks, 0);
		world.setBlockMetadataWithNotify(i + 1, j + 5, k + 19, 5, 2);
		this.setBlock(world, i + 1, j + 5, k + 20, Blocks.planks, 0);
		world.setBlockMetadataWithNotify(i + 1, j + 5, k + 20, 5, 2);
		this.setBlock(world, i + 1, j + 5, k + 21, Blocks.planks, 0);
		world.setBlockMetadataWithNotify(i + 1, j + 5, k + 21, 5, 2);
		this.setBlock(world, i + 1, j + 5, k + 22, Blocks.planks, 0);
		world.setBlockMetadataWithNotify(i + 1, j + 5, k + 22, 5, 2);
		this.setBlock(world, i + 1, j + 5, k + 23, Blocks.planks, 0);
		world.setBlockMetadataWithNotify(i + 1, j + 5, k + 23, 5, 2);
		this.setBlock(world, i + 1, j + 5, k + 24, Blocks.planks, 0);
		world.setBlockMetadataWithNotify(i + 1, j + 5, k + 24, 5, 2);
		this.setBlock(world, i + 1, j + 5, k + 25, Blocks.planks, 0);
		world.setBlockMetadataWithNotify(i + 1, j + 5, k + 25, 5, 2);
		this.setBlock(world, i + 1, j + 5, k + 26, Blocks.planks, 0);
		world.setBlockMetadataWithNotify(i + 1, j + 5, k + 26, 5, 2);
		this.setBlock(world, i + 1, j + 5, k + 27, Blocks.planks, 0);
		world.setBlockMetadataWithNotify(i + 1, j + 5, k + 27, 5, 2);
		this.setBlock(world, i + 1, j + 5, k + 28, Blocks.planks, 0);
		world.setBlockMetadataWithNotify(i + 1, j + 5, k + 28, 5, 2);
		this.setBlock(world, i + 1, j + 5, k + 29, Blocks.planks, 0);
		world.setBlockMetadataWithNotify(i + 1, j + 5, k + 29, 5, 2);
		this.setBlock(world, i + 1, j + 5, k + 30, Blocks.planks, 0);
		world.setBlockMetadataWithNotify(i + 1, j + 5, k + 30, 5, 2);
		this.setBlock(world, i + 1, j + 5, k + 31, Blocks.air, 0);
		this.setBlock(world, i + 1, j + 5, k + 32, Blocks.air, 0);
		this.setBlock(world, i + 1, j + 5, k + 33, Blocks.air, 0);
		this.setBlock(world, i + 1, j + 5, k + 34, Blocks.air, 0);
		this.setBlock(world, i + 1, j + 6, k + 0, Blocks.air, 0);
		this.setBlock(world, i + 1, j + 6, k + 1, Blocks.air, 0);
		this.setBlock(world, i + 1, j + 6, k + 2, Blocks.air, 0);
		this.setBlock(world, i + 1, j + 6, k + 3, Blocks.air, 0);
		this.setBlock(world, i + 1, j + 6, k + 4, Blocks.air, 0);
		this.setBlock(world, i + 1, j + 6, k + 5, Blocks.air, 0);
		this.setBlock(world, i + 1, j + 6, k + 6, Blocks.air, 0);
		this.setBlock(world, i + 1, j + 6, k + 7, Blocks.air, 0);
		this.setBlock(world, i + 1, j + 6, k + 8, Blocks.air, 0);
		this.setBlock(world, i + 1, j + 6, k + 9, Blocks.air, 0);
		this.setBlock(world, i + 1, j + 6, k + 10, Blocks.air, 0);
		generate_1(world, rand, i, j, k);
		return true;
	}

	public boolean generate_1(World world, Random rand, int i, int j, int k)
	{
		this.setBlock(world, i + 1, j + 6, k + 11, Blocks.air, 0);
		this.setBlock(world, i + 1, j + 6, k + 12, Blocks.air, 0);
		this.setBlock(world, i + 1, j + 6, k + 13, Blocks.air, 0);
		this.setBlock(world, i + 1, j + 6, k + 14, Blocks.air, 0);
		this.setBlock(world, i + 1, j + 6, k + 15, Blocks.air, 0);
		this.setBlock(world, i + 1, j + 6, k + 16, Blocks.air, 0);
		this.setBlock(world, i + 1, j + 6, k + 17, Blocks.air, 0);
		this.setBlock(world, i + 1, j + 6, k + 18, Blocks.air, 0);
		this.setBlock(world, i + 1, j + 6, k + 19, Blocks.air, 0);
		this.setBlock(world, i + 1, j + 6, k + 20, Blocks.air, 0);
		this.setBlock(world, i + 1, j + 6, k + 21, Blocks.air, 0);
		this.setBlock(world, i + 1, j + 6, k + 22, Blocks.air, 0);
		this.setBlock(world, i + 1, j + 6, k + 23, Blocks.air, 0);
		this.setBlock(world, i + 1, j + 6, k + 24, Blocks.air, 0);
		this.setBlock(world, i + 1, j + 6, k + 25, Blocks.air, 0);
		this.setBlock(world, i + 1, j + 6, k + 26, Blocks.air, 0);
		this.setBlock(world, i + 1, j + 6, k + 27, Blocks.air, 0);
		this.setBlock(world, i + 1, j + 6, k + 28, Blocks.air, 0);
		this.setBlock(world, i + 1, j + 6, k + 29, Blocks.air, 0);
		this.setBlock(world, i + 1, j + 6, k + 30, Blocks.air, 0);
		this.setBlock(world, i + 1, j + 6, k + 31, Blocks.air, 0);
		this.setBlock(world, i + 1, j + 6, k + 32, Blocks.air, 0);
		this.setBlock(world, i + 1, j + 6, k + 33, Blocks.air, 0);
		this.setBlock(world, i + 1, j + 6, k + 34, Blocks.air, 0);
		this.setBlock(world, i + 1, j + 7, k + 0, Blocks.air, 0);
		this.setBlock(world, i + 1, j + 7, k + 1, Blocks.air, 0);
		this.setBlock(world, i + 1, j + 7, k + 2, Blocks.air, 0);
		this.setBlock(world, i + 1, j + 7, k + 3, Blocks.air, 0);
		this.setBlock(world, i + 1, j + 7, k + 4, Blocks.air, 0);
		this.setBlock(world, i + 1, j + 7, k + 5, Blocks.air, 0);
		this.setBlock(world, i + 1, j + 7, k + 6, Blocks.air, 0);
		this.setBlock(world, i + 1, j + 7, k + 7, Blocks.air, 0);
		this.setBlock(world, i + 1, j + 7, k + 8, Blocks.air, 0);
		this.setBlock(world, i + 1, j + 7, k + 9, Blocks.air, 0);
		this.setBlock(world, i + 1, j + 7, k + 10, Blocks.air, 0);
		this.setBlock(world, i + 1, j + 7, k + 11, Blocks.air, 0);
		this.setBlock(world, i + 1, j + 7, k + 12, Blocks.air, 0);
		this.setBlock(world, i + 1, j + 7, k + 13, Blocks.air, 0);
		this.setBlock(world, i + 1, j + 7, k + 14, Blocks.air, 0);
		this.setBlock(world, i + 1, j + 7, k + 15, Blocks.air, 0);
		this.setBlock(world, i + 1, j + 7, k + 16, Blocks.air, 0);
		this.setBlock(world, i + 1, j + 7, k + 17, Blocks.air, 0);
		this.setBlock(world, i + 1, j + 7, k + 18, Blocks.air, 0);
		this.setBlock(world, i + 1, j + 7, k + 19, Blocks.air, 0);
		this.setBlock(world, i + 1, j + 7, k + 20, Blocks.air, 0);
		this.setBlock(world, i + 1, j + 7, k + 21, Blocks.air, 0);
		this.setBlock(world, i + 1, j + 7, k + 22, Blocks.air, 0);
		this.setBlock(world, i + 1, j + 7, k + 23, Blocks.air, 0);
		this.setBlock(world, i + 1, j + 7, k + 24, Blocks.air, 0);
		this.setBlock(world, i + 1, j + 7, k + 25, Blocks.air, 0);
		this.setBlock(world, i + 1, j + 7, k + 26, Blocks.air, 0);
		this.setBlock(world, i + 1, j + 7, k + 27, Blocks.air, 0);
		this.setBlock(world, i + 1, j + 7, k + 28, Blocks.air, 0);
		this.setBlock(world, i + 1, j + 7, k + 29, Blocks.air, 0);
		this.setBlock(world, i + 1, j + 7, k + 30, Blocks.air, 0);
		this.setBlock(world, i + 1, j + 7, k + 31, Blocks.air, 0);
		this.setBlock(world, i + 1, j + 7, k + 32, Blocks.air, 0);
		this.setBlock(world, i + 1, j + 7, k + 33, Blocks.air, 0);
		this.setBlock(world, i + 1, j + 7, k + 34, Blocks.air, 0);
		this.setBlock(world, i + 2, j + 0, k + 0, Blocks.grass, 0);
		this.setBlock(world, i + 2, j + 0, k + 1, Blocks.grass, 0);
		this.setBlock(world, i + 2, j + 0, k + 2, Blocks.grass, 0);
		this.setBlock(world, i + 2, j + 0, k + 3, Blocks.grass, 0);
		this.setBlock(world, i + 2, j + 0, k + 4, Blocks.grass, 0);
		this.setBlock(world, i + 2, j + 0, k + 5, Blocks.grass, 0);
		this.setBlock(world, i + 2, j + 0, k + 6, Blocks.grass, 0);
		this.setBlock(world, i + 2, j + 0, k + 7, Blocks.grass, 0);
		this.setBlock(world, i + 2, j + 0, k + 8, Blocks.grass, 0);
		this.setBlock(world, i + 2, j + 0, k + 9, Blocks.grass, 0);
		this.setBlock(world, i + 2, j + 0, k + 10, Blocks.grass, 0);
		this.setBlock(world, i + 2, j + 0, k + 11, Blocks.grass, 0);
		this.setBlock(world, i + 2, j + 0, k + 12, Blocks.grass, 0);
		this.setBlock(world, i + 2, j + 0, k + 13, Blocks.grass, 0);
		this.setBlock(world, i + 2, j + 0, k + 14, Blocks.grass, 0);
		this.setBlock(world, i + 2, j + 0, k + 15, Blocks.grass, 0);
		this.setBlock(world, i + 2, j + 0, k + 16, Blocks.grass, 0);
		this.setBlock(world, i + 2, j + 0, k + 17, Blocks.grass, 0);
		this.setBlock(world, i + 2, j + 0, k + 18, Blocks.grass, 0);
		this.setBlock(world, i + 2, j + 0, k + 19, Blocks.grass, 0);
		this.setBlock(world, i + 2, j + 0, k + 20, Blocks.grass, 0);
		this.setBlock(world, i + 2, j + 0, k + 21, Blocks.grass, 0);
		this.setBlock(world, i + 2, j + 0, k + 22, Blocks.grass, 0);
		this.setBlock(world, i + 2, j + 0, k + 23, Blocks.grass, 0);
		this.setBlock(world, i + 2, j + 0, k + 24, Blocks.grass, 0);
		this.setBlock(world, i + 2, j + 0, k + 25, Blocks.grass, 0);
		this.setBlock(world, i + 2, j + 0, k + 26, Blocks.grass, 0);
		this.setBlock(world, i + 2, j + 0, k + 27, Blocks.grass, 0);
		this.setBlock(world, i + 2, j + 0, k + 28, Blocks.grass, 0);
		this.setBlock(world, i + 2, j + 0, k + 29, Blocks.grass, 0);
		this.setBlock(world, i + 2, j + 0, k + 30, Blocks.grass, 0);
		this.setBlock(world, i + 2, j + 0, k + 31, Blocks.grass, 0);
		this.setBlock(world, i + 2, j + 0, k + 32, Blocks.grass, 0);
		this.setBlock(world, i + 2, j + 0, k + 33, Blocks.grass, 0);
		this.setBlock(world, i + 2, j + 0, k + 34, Blocks.grass, 0);
		this.setBlock(world, i + 2, j + 1, k + 0, Blocks.air, 0);
		this.setBlock(world, i + 2, j + 1, k + 1, Blocks.air, 0);
		this.setBlock(world, i + 2, j + 1, k + 2, Blocks.air, 0);
		this.setBlock(world, i + 2, j + 1, k + 3, Blocks.air, 0);
		this.setBlock(world, i + 2, j + 1, k + 4, Blocks.air, 0);
		this.setBlock(world, i + 2, j + 1, k + 5, StarWarsMod.blockEndorBaseWall, 0);
		world.setBlockMetadataWithNotify(i + 2, j + 1, k + 5, 1, 2);
		this.setBlock(world, i + 2, j + 1, k + 6, StarWarsMod.blockEndorBaseWall, 0);
		world.setBlockMetadataWithNotify(i + 2, j + 1, k + 6, 1, 2);
		this.setBlock(world, i + 2, j + 1, k + 7, StarWarsMod.blockEndorBaseWall, 0);
		world.setBlockMetadataWithNotify(i + 2, j + 1, k + 7, 1, 2);
		this.setBlock(world, i + 2, j + 1, k + 8, StarWarsMod.blockEndorBaseWall, 0);
		world.setBlockMetadataWithNotify(i + 2, j + 1, k + 8, 1, 2);
		this.setBlock(world, i + 2, j + 1, k + 9, StarWarsMod.blockEndorBaseWall, 0);
		world.setBlockMetadataWithNotify(i + 2, j + 1, k + 9, 1, 2);
		this.setBlock(world, i + 2, j + 1, k + 10, StarWarsMod.blockEndorBaseWall, 0);
		world.setBlockMetadataWithNotify(i + 2, j + 1, k + 10, 1, 2);
		this.setBlock(world, i + 2, j + 1, k + 11, StarWarsMod.blockEndorBaseWall, 0);
		world.setBlockMetadataWithNotify(i + 2, j + 1, k + 11, 1, 2);
		this.setBlock(world, i + 2, j + 1, k + 12, StarWarsMod.blockEndorBaseWall, 0);
		world.setBlockMetadataWithNotify(i + 2, j + 1, k + 12, 1, 2);
		this.setBlock(world, i + 2, j + 1, k + 13, StarWarsMod.blockEndorBaseWall, 0);
		world.setBlockMetadataWithNotify(i + 2, j + 1, k + 13, 1, 2);
		this.setBlock(world, i + 2, j + 1, k + 14, StarWarsMod.blockEndorBaseWall, 0);
		world.setBlockMetadataWithNotify(i + 2, j + 1, k + 14, 1, 2);
		this.setBlock(world, i + 2, j + 1, k + 15, Blocks.quartz_block, 0);
		this.setBlock(world, i + 2, j + 1, k + 16, StarWarsMod.blockEndorBaseWall, 0);
		world.setBlockMetadataWithNotify(i + 2, j + 1, k + 16, 1, 2);
		this.setBlock(world, i + 2, j + 1, k + 17, StarWarsMod.blockEndorBaseWall, 0);
		world.setBlockMetadataWithNotify(i + 2, j + 1, k + 17, 1, 2);
		this.setBlock(world, i + 2, j + 1, k + 18, StarWarsMod.blockEndorBaseWall, 0);
		world.setBlockMetadataWithNotify(i + 2, j + 1, k + 18, 1, 2);
		this.setBlock(world, i + 2, j + 1, k + 19, Blocks.quartz_block, 0);
		this.setBlock(world, i + 2, j + 1, k + 20, StarWarsMod.blockEndorBaseWall, 0);
		world.setBlockMetadataWithNotify(i + 2, j + 1, k + 20, 1, 2);
		this.setBlock(world, i + 2, j + 1, k + 21, StarWarsMod.blockEndorBaseWall, 0);
		world.setBlockMetadataWithNotify(i + 2, j + 1, k + 21, 1, 2);
		this.setBlock(world, i + 2, j + 1, k + 22, StarWarsMod.blockEndorBaseWall, 0);
		world.setBlockMetadataWithNotify(i + 2, j + 1, k + 22, 1, 2);
		this.setBlock(world, i + 2, j + 1, k + 23, StarWarsMod.blockEndorBaseWall, 0);
		world.setBlockMetadataWithNotify(i + 2, j + 1, k + 23, 1, 2);
		this.setBlock(world, i + 2, j + 1, k + 24, StarWarsMod.blockEndorBaseWall, 0);
		world.setBlockMetadataWithNotify(i + 2, j + 1, k + 24, 1, 2);
		this.setBlock(world, i + 2, j + 1, k + 25, StarWarsMod.blockEndorBaseWall, 0);
		world.setBlockMetadataWithNotify(i + 2, j + 1, k + 25, 1, 2);
		this.setBlock(world, i + 2, j + 1, k + 26, StarWarsMod.blockEndorBaseWall, 0);
		world.setBlockMetadataWithNotify(i + 2, j + 1, k + 26, 1, 2);
		this.setBlock(world, i + 2, j + 1, k + 27, StarWarsMod.blockEndorBaseWall, 0);
		world.setBlockMetadataWithNotify(i + 2, j + 1, k + 27, 1, 2);
		this.setBlock(world, i + 2, j + 1, k + 28, StarWarsMod.blockEndorBaseWall, 0);
		world.setBlockMetadataWithNotify(i + 2, j + 1, k + 28, 1, 2);
		this.setBlock(world, i + 2, j + 1, k + 29, StarWarsMod.blockEndorBaseWall, 0);
		world.setBlockMetadataWithNotify(i + 2, j + 1, k + 29, 1, 2);
		this.setBlock(world, i + 2, j + 1, k + 30, Blocks.air, 0);
		this.setBlock(world, i + 2, j + 1, k + 31, Blocks.air, 0);
		this.setBlock(world, i + 2, j + 1, k + 32, Blocks.air, 0);
		this.setBlock(world, i + 2, j + 1, k + 33, Blocks.air, 0);
		this.setBlock(world, i + 2, j + 1, k + 34, Blocks.air, 0);
		this.setBlock(world, i + 2, j + 2, k + 0, Blocks.air, 0);
		this.setBlock(world, i + 2, j + 2, k + 1, Blocks.air, 0);
		this.setBlock(world, i + 2, j + 2, k + 2, Blocks.air, 0);
		this.setBlock(world, i + 2, j + 2, k + 3, Blocks.air, 0);
		this.setBlock(world, i + 2, j + 2, k + 4, Blocks.air, 0);
		this.setBlock(world, i + 2, j + 2, k + 5, StarWarsMod.blockEndorBaseWall, 0);
		world.setBlockMetadataWithNotify(i + 2, j + 2, k + 5, 1, 2);
		this.setBlock(world, i + 2, j + 2, k + 6, StarWarsMod.blockEndorBaseWall, 0);
		world.setBlockMetadataWithNotify(i + 2, j + 2, k + 6, 1, 2);
		this.setBlock(world, i + 2, j + 2, k + 7, StarWarsMod.blockEndorBaseWall, 0);
		world.setBlockMetadataWithNotify(i + 2, j + 2, k + 7, 1, 2);
		this.setBlock(world, i + 2, j + 2, k + 8, StarWarsMod.blockEndorBaseWall, 0);
		world.setBlockMetadataWithNotify(i + 2, j + 2, k + 8, 1, 2);
		this.setBlock(world, i + 2, j + 2, k + 9, StarWarsMod.blockEndorBaseWall, 0);
		world.setBlockMetadataWithNotify(i + 2, j + 2, k + 9, 1, 2);
		this.setBlock(world, i + 2, j + 2, k + 10, StarWarsMod.blockEndorBaseWall, 0);
		world.setBlockMetadataWithNotify(i + 2, j + 2, k + 10, 1, 2);
		this.setBlock(world, i + 2, j + 2, k + 11, StarWarsMod.blockEndorBaseWall, 0);
		world.setBlockMetadataWithNotify(i + 2, j + 2, k + 11, 1, 2);
		this.setBlock(world, i + 2, j + 2, k + 12, StarWarsMod.blockEndorBaseWall, 0);
		world.setBlockMetadataWithNotify(i + 2, j + 2, k + 12, 1, 2);
		this.setBlock(world, i + 2, j + 2, k + 13, Blocks.quartz_block, 0);
		this.setBlock(world, i + 2, j + 2, k + 14, StarWarsMod.blockEndorBaseWall, 0);
		world.setBlockMetadataWithNotify(i + 2, j + 2, k + 14, 3, 2);
		this.setBlock(world, i + 2, j + 2, k + 15, StarWarsMod.blockEndorBaseWall, 0);
		world.setBlockMetadataWithNotify(i + 2, j + 2, k + 15, 4, 2);
		this.setBlock(world, i + 2, j + 2, k + 16, StarWarsMod.blockEndorBaseWall, 0);
		world.setBlockMetadataWithNotify(i + 2, j + 2, k + 16, 3, 2);
		this.setBlock(world, i + 2, j + 2, k + 17, Blocks.quartz_block, 0);
		this.setBlock(world, i + 2, j + 2, k + 18, StarWarsMod.blockEndorBaseWall, 0);
		world.setBlockMetadataWithNotify(i + 2, j + 2, k + 18, 3, 2);
		this.setBlock(world, i + 2, j + 2, k + 19, StarWarsMod.blockEndorBaseWall, 0);
		world.setBlockMetadataWithNotify(i + 2, j + 2, k + 19, 4, 2);
		this.setBlock(world, i + 2, j + 2, k + 20, StarWarsMod.blockEndorBaseWall, 0);
		world.setBlockMetadataWithNotify(i + 2, j + 2, k + 20, 3, 2);
		this.setBlock(world, i + 2, j + 2, k + 21, Blocks.quartz_block, 0);
		this.setBlock(world, i + 2, j + 2, k + 22, StarWarsMod.blockEndorBaseWall, 0);
		world.setBlockMetadataWithNotify(i + 2, j + 2, k + 22, 1, 2);
		this.setBlock(world, i + 2, j + 2, k + 23, StarWarsMod.blockEndorBaseWall, 0);
		world.setBlockMetadataWithNotify(i + 2, j + 2, k + 23, 1, 2);
		this.setBlock(world, i + 2, j + 2, k + 24, StarWarsMod.blockEndorBaseWall, 0);
		world.setBlockMetadataWithNotify(i + 2, j + 2, k + 24, 1, 2);
		this.setBlock(world, i + 2, j + 2, k + 25, StarWarsMod.blockEndorBaseWall, 0);
		world.setBlockMetadataWithNotify(i + 2, j + 2, k + 25, 1, 2);
		this.setBlock(world, i + 2, j + 2, k + 26, StarWarsMod.blockEndorBaseWall, 0);
		world.setBlockMetadataWithNotify(i + 2, j + 2, k + 26, 1, 2);
		this.setBlock(world, i + 2, j + 2, k + 27, StarWarsMod.blockEndorBaseWall, 0);
		world.setBlockMetadataWithNotify(i + 2, j + 2, k + 27, 1, 2);
		this.setBlock(world, i + 2, j + 2, k + 28, StarWarsMod.blockEndorBaseWall, 0);
		world.setBlockMetadataWithNotify(i + 2, j + 2, k + 28, 1, 2);
		this.setBlock(world, i + 2, j + 2, k + 29, StarWarsMod.blockEndorBaseWall, 0);
		world.setBlockMetadataWithNotify(i + 2, j + 2, k + 29, 1, 2);
		this.setBlock(world, i + 2, j + 2, k + 30, Blocks.air, 0);
		this.setBlock(world, i + 2, j + 2, k + 31, Blocks.air, 0);
		this.setBlock(world, i + 2, j + 2, k + 32, Blocks.air, 0);
		this.setBlock(world, i + 2, j + 2, k + 33, Blocks.air, 0);
		this.setBlock(world, i + 2, j + 2, k + 34, Blocks.air, 0);
		this.setBlock(world, i + 2, j + 3, k + 0, Blocks.air, 0);
		this.setBlock(world, i + 2, j + 3, k + 1, Blocks.air, 0);
		this.setBlock(world, i + 2, j + 3, k + 2, Blocks.air, 0);
		this.setBlock(world, i + 2, j + 3, k + 3, Blocks.air, 0);
		this.setBlock(world, i + 2, j + 3, k + 4, Blocks.air, 0);
		this.setBlock(world, i + 2, j + 3, k + 5, StarWarsMod.blockEndorBaseWall, 0);
		world.setBlockMetadataWithNotify(i + 2, j + 3, k + 5, 1, 2);
		this.setBlock(world, i + 2, j + 3, k + 6, StarWarsMod.blockEndorBaseWall, 0);
		world.setBlockMetadataWithNotify(i + 2, j + 3, k + 6, 1, 2);
		this.setBlock(world, i + 2, j + 3, k + 7, StarWarsMod.blockEndorBaseWall, 0);
		world.setBlockMetadataWithNotify(i + 2, j + 3, k + 7, 1, 2);
		this.setBlock(world, i + 2, j + 3, k + 8, StarWarsMod.blockEndorBaseWall, 0);
		world.setBlockMetadataWithNotify(i + 2, j + 3, k + 8, 1, 2);
		this.setBlock(world, i + 2, j + 3, k + 9, StarWarsMod.blockEndorBaseWall, 0);
		world.setBlockMetadataWithNotify(i + 2, j + 3, k + 9, 1, 2);
		this.setBlock(world, i + 2, j + 3, k + 10, StarWarsMod.blockEndorBaseWall, 0);
		world.setBlockMetadataWithNotify(i + 2, j + 3, k + 10, 1, 2);
		this.setBlock(world, i + 2, j + 3, k + 11, StarWarsMod.blockEndorBaseWall, 0);
		world.setBlockMetadataWithNotify(i + 2, j + 3, k + 11, 1, 2);
		this.setBlock(world, i + 2, j + 3, k + 12, StarWarsMod.blockEndorBaseWall, 0);
		world.setBlockMetadataWithNotify(i + 2, j + 3, k + 12, 1, 2);
		this.setBlock(world, i + 2, j + 3, k + 13, Blocks.quartz_block, 0);
		this.setBlock(world, i + 2, j + 3, k + 14, StarWarsMod.blockEndorBaseWall, 0);
		world.setBlockMetadataWithNotify(i + 2, j + 3, k + 14, 4, 2);
		this.setBlock(world, i + 2, j + 3, k + 15, StarWarsMod.blockEndorBaseWall, 0);
		world.setBlockMetadataWithNotify(i + 2, j + 3, k + 15, 3, 2);
		this.setBlock(world, i + 2, j + 3, k + 16, StarWarsMod.blockEndorBaseWall, 0);
		world.setBlockMetadataWithNotify(i + 2, j + 3, k + 16, 4, 2);
		this.setBlock(world, i + 2, j + 3, k + 17, Blocks.quartz_block, 0);
		this.setBlock(world, i + 2, j + 3, k + 18, StarWarsMod.blockEndorBaseWall, 0);
		world.setBlockMetadataWithNotify(i + 2, j + 3, k + 18, 4, 2);
		this.setBlock(world, i + 2, j + 3, k + 19, StarWarsMod.blockEndorBaseWall, 0);
		world.setBlockMetadataWithNotify(i + 2, j + 3, k + 19, 3, 2);
		this.setBlock(world, i + 2, j + 3, k + 20, StarWarsMod.blockEndorBaseWall, 0);
		world.setBlockMetadataWithNotify(i + 2, j + 3, k + 20, 4, 2);
		this.setBlock(world, i + 2, j + 3, k + 21, Blocks.quartz_block, 0);
		this.setBlock(world, i + 2, j + 3, k + 22, StarWarsMod.blockEndorBaseWall, 0);
		world.setBlockMetadataWithNotify(i + 2, j + 3, k + 22, 1, 2);
		this.setBlock(world, i + 2, j + 3, k + 23, StarWarsMod.blockEndorBaseWall, 0);
		world.setBlockMetadataWithNotify(i + 2, j + 3, k + 23, 1, 2);
		this.setBlock(world, i + 2, j + 3, k + 24, StarWarsMod.blockEndorBaseWall, 0);
		world.setBlockMetadataWithNotify(i + 2, j + 3, k + 24, 1, 2);
		this.setBlock(world, i + 2, j + 3, k + 25, StarWarsMod.blockEndorBaseWall, 0);
		world.setBlockMetadataWithNotify(i + 2, j + 3, k + 25, 1, 2);
		this.setBlock(world, i + 2, j + 3, k + 26, StarWarsMod.blockEndorBaseWall, 0);
		world.setBlockMetadataWithNotify(i + 2, j + 3, k + 26, 1, 2);
		this.setBlock(world, i + 2, j + 3, k + 27, StarWarsMod.blockEndorBaseWall, 0);
		world.setBlockMetadataWithNotify(i + 2, j + 3, k + 27, 1, 2);
		this.setBlock(world, i + 2, j + 3, k + 28, StarWarsMod.blockEndorBaseWall, 0);
		world.setBlockMetadataWithNotify(i + 2, j + 3, k + 28, 1, 2);
		this.setBlock(world, i + 2, j + 3, k + 29, StarWarsMod.blockEndorBaseWall, 0);
		world.setBlockMetadataWithNotify(i + 2, j + 3, k + 29, 1, 2);
		this.setBlock(world, i + 2, j + 3, k + 30, Blocks.air, 0);
		this.setBlock(world, i + 2, j + 3, k + 31, Blocks.air, 0);
		this.setBlock(world, i + 2, j + 3, k + 32, Blocks.air, 0);
		this.setBlock(world, i + 2, j + 3, k + 33, Blocks.air, 0);
		this.setBlock(world, i + 2, j + 3, k + 34, Blocks.air, 0);
		this.setBlock(world, i + 2, j + 4, k + 0, Blocks.air, 0);
		this.setBlock(world, i + 2, j + 4, k + 1, Blocks.air, 0);
		this.setBlock(world, i + 2, j + 4, k + 2, Blocks.air, 0);
		this.setBlock(world, i + 2, j + 4, k + 3, Blocks.air, 0);
		this.setBlock(world, i + 2, j + 4, k + 4, Blocks.air, 0);
		this.setBlock(world, i + 2, j + 4, k + 5, StarWarsMod.blockEndorBaseWall, 0);
		world.setBlockMetadataWithNotify(i + 2, j + 4, k + 5, 1, 2);
		this.setBlock(world, i + 2, j + 4, k + 6, StarWarsMod.blockEndorBaseWall, 0);
		world.setBlockMetadataWithNotify(i + 2, j + 4, k + 6, 1, 2);
		this.setBlock(world, i + 2, j + 4, k + 7, StarWarsMod.blockEndorBaseWall, 0);
		world.setBlockMetadataWithNotify(i + 2, j + 4, k + 7, 1, 2);
		this.setBlock(world, i + 2, j + 4, k + 8, StarWarsMod.blockEndorBaseWall, 0);
		world.setBlockMetadataWithNotify(i + 2, j + 4, k + 8, 1, 2);
		this.setBlock(world, i + 2, j + 4, k + 9, StarWarsMod.blockEndorBaseWall, 0);
		world.setBlockMetadataWithNotify(i + 2, j + 4, k + 9, 1, 2);
		this.setBlock(world, i + 2, j + 4, k + 10, StarWarsMod.blockEndorBaseWall, 0);
		world.setBlockMetadataWithNotify(i + 2, j + 4, k + 10, 1, 2);
		this.setBlock(world, i + 2, j + 4, k + 11, StarWarsMod.blockEndorBaseWall, 0);
		world.setBlockMetadataWithNotify(i + 2, j + 4, k + 11, 1, 2);
		this.setBlock(world, i + 2, j + 4, k + 12, StarWarsMod.blockEndorBaseWall, 0);
		world.setBlockMetadataWithNotify(i + 2, j + 4, k + 12, 1, 2);
		this.setBlock(world, i + 2, j + 4, k + 13, StarWarsMod.blockEndorBaseWall, 0);
		world.setBlockMetadataWithNotify(i + 2, j + 4, k + 13, 1, 2);
		this.setBlock(world, i + 2, j + 4, k + 14, StarWarsMod.blockEndorBaseWall, 0);
		world.setBlockMetadataWithNotify(i + 2, j + 4, k + 14, 1, 2);
		this.setBlock(world, i + 2, j + 4, k + 15, Blocks.quartz_block, 0);
		this.setBlock(world, i + 2, j + 4, k + 16, StarWarsMod.blockEndorBaseWall, 0);
		world.setBlockMetadataWithNotify(i + 2, j + 4, k + 16, 1, 2);
		this.setBlock(world, i + 2, j + 4, k + 17, StarWarsMod.blockEndorBaseWall, 0);
		world.setBlockMetadataWithNotify(i + 2, j + 4, k + 17, 1, 2);
		this.setBlock(world, i + 2, j + 4, k + 18, StarWarsMod.blockEndorBaseWall, 0);
		world.setBlockMetadataWithNotify(i + 2, j + 4, k + 18, 1, 2);
		this.setBlock(world, i + 2, j + 4, k + 19, Blocks.quartz_block, 0);
		this.setBlock(world, i + 2, j + 4, k + 20, StarWarsMod.blockEndorBaseWall, 0);
		world.setBlockMetadataWithNotify(i + 2, j + 4, k + 20, 1, 2);
		this.setBlock(world, i + 2, j + 4, k + 21, StarWarsMod.blockEndorBaseWall, 0);
		world.setBlockMetadataWithNotify(i + 2, j + 4, k + 21, 1, 2);
		this.setBlock(world, i + 2, j + 4, k + 22, StarWarsMod.blockEndorBaseWall, 0);
		world.setBlockMetadataWithNotify(i + 2, j + 4, k + 22, 1, 2);
		this.setBlock(world, i + 2, j + 4, k + 23, StarWarsMod.blockEndorBaseWall, 0);
		world.setBlockMetadataWithNotify(i + 2, j + 4, k + 23, 1, 2);
		this.setBlock(world, i + 2, j + 4, k + 24, StarWarsMod.blockEndorBaseWall, 0);
		world.setBlockMetadataWithNotify(i + 2, j + 4, k + 24, 1, 2);
		this.setBlock(world, i + 2, j + 4, k + 25, StarWarsMod.blockEndorBaseWall, 0);
		world.setBlockMetadataWithNotify(i + 2, j + 4, k + 25, 1, 2);
		this.setBlock(world, i + 2, j + 4, k + 26, StarWarsMod.blockEndorBaseWall, 0);
		world.setBlockMetadataWithNotify(i + 2, j + 4, k + 26, 1, 2);
		this.setBlock(world, i + 2, j + 4, k + 27, StarWarsMod.blockEndorBaseWall, 0);
		world.setBlockMetadataWithNotify(i + 2, j + 4, k + 27, 1, 2);
		this.setBlock(world, i + 2, j + 4, k + 28, StarWarsMod.blockEndorBaseWall, 0);
		world.setBlockMetadataWithNotify(i + 2, j + 4, k + 28, 1, 2);
		this.setBlock(world, i + 2, j + 4, k + 29, StarWarsMod.blockEndorBaseWall, 0);
		world.setBlockMetadataWithNotify(i + 2, j + 4, k + 29, 1, 2);
		this.setBlock(world, i + 2, j + 4, k + 30, Blocks.air, 0);
		this.setBlock(world, i + 2, j + 4, k + 31, Blocks.air, 0);
		this.setBlock(world, i + 2, j + 4, k + 32, Blocks.air, 0);
		this.setBlock(world, i + 2, j + 4, k + 33, Blocks.air, 0);
		this.setBlock(world, i + 2, j + 4, k + 34, Blocks.air, 0);
		this.setBlock(world, i + 2, j + 5, k + 0, Blocks.air, 0);
		this.setBlock(world, i + 2, j + 5, k + 1, Blocks.air, 0);
		this.setBlock(world, i + 2, j + 5, k + 2, Blocks.air, 0);
		this.setBlock(world, i + 2, j + 5, k + 3, Blocks.planks, 0);
		world.setBlockMetadataWithNotify(i + 2, j + 5, k + 3, 5, 2);
		this.setBlock(world, i + 2, j + 5, k + 4, Blocks.planks, 0);
		world.setBlockMetadataWithNotify(i + 2, j + 5, k + 4, 5, 2);
		this.setBlock(world, i + 2, j + 5, k + 5, Blocks.planks, 0);
		world.setBlockMetadataWithNotify(i + 2, j + 5, k + 5, 5, 2);
		this.setBlock(world, i + 2, j + 5, k + 6, Blocks.planks, 0);
		world.setBlockMetadataWithNotify(i + 2, j + 5, k + 6, 5, 2);
		this.setBlock(world, i + 2, j + 5, k + 7, Blocks.planks, 0);
		world.setBlockMetadataWithNotify(i + 2, j + 5, k + 7, 5, 2);
		this.setBlock(world, i + 2, j + 5, k + 8, Blocks.planks, 0);
		world.setBlockMetadataWithNotify(i + 2, j + 5, k + 8, 5, 2);
		this.setBlock(world, i + 2, j + 5, k + 9, Blocks.planks, 0);
		world.setBlockMetadataWithNotify(i + 2, j + 5, k + 9, 5, 2);
		this.setBlock(world, i + 2, j + 5, k + 10, Blocks.planks, 0);
		world.setBlockMetadataWithNotify(i + 2, j + 5, k + 10, 5, 2);
		this.setBlock(world, i + 2, j + 5, k + 11, Blocks.planks, 0);
		world.setBlockMetadataWithNotify(i + 2, j + 5, k + 11, 5, 2);
		this.setBlock(world, i + 2, j + 5, k + 12, Blocks.planks, 0);
		world.setBlockMetadataWithNotify(i + 2, j + 5, k + 12, 5, 2);
		this.setBlock(world, i + 2, j + 5, k + 13, Blocks.planks, 0);
		world.setBlockMetadataWithNotify(i + 2, j + 5, k + 13, 5, 2);
		this.setBlock(world, i + 2, j + 5, k + 14, Blocks.planks, 0);
		world.setBlockMetadataWithNotify(i + 2, j + 5, k + 14, 5, 2);
		this.setBlock(world, i + 2, j + 5, k + 15, Blocks.planks, 0);
		world.setBlockMetadataWithNotify(i + 2, j + 5, k + 15, 5, 2);
		this.setBlock(world, i + 2, j + 5, k + 16, Blocks.planks, 0);
		world.setBlockMetadataWithNotify(i + 2, j + 5, k + 16, 5, 2);
		this.setBlock(world, i + 2, j + 5, k + 17, Blocks.planks, 0);
		world.setBlockMetadataWithNotify(i + 2, j + 5, k + 17, 5, 2);
		this.setBlock(world, i + 2, j + 5, k + 18, Blocks.planks, 0);
		world.setBlockMetadataWithNotify(i + 2, j + 5, k + 18, 5, 2);
		this.setBlock(world, i + 2, j + 5, k + 19, Blocks.planks, 0);
		world.setBlockMetadataWithNotify(i + 2, j + 5, k + 19, 5, 2);
		this.setBlock(world, i + 2, j + 5, k + 20, Blocks.planks, 0);
		world.setBlockMetadataWithNotify(i + 2, j + 5, k + 20, 5, 2);
		this.setBlock(world, i + 2, j + 5, k + 21, Blocks.planks, 0);
		world.setBlockMetadataWithNotify(i + 2, j + 5, k + 21, 5, 2);
		this.setBlock(world, i + 2, j + 5, k + 22, Blocks.planks, 0);
		world.setBlockMetadataWithNotify(i + 2, j + 5, k + 22, 5, 2);
		this.setBlock(world, i + 2, j + 5, k + 23, Blocks.planks, 0);
		world.setBlockMetadataWithNotify(i + 2, j + 5, k + 23, 5, 2);
		this.setBlock(world, i + 2, j + 5, k + 24, Blocks.planks, 0);
		world.setBlockMetadataWithNotify(i + 2, j + 5, k + 24, 5, 2);
		this.setBlock(world, i + 2, j + 5, k + 25, Blocks.planks, 0);
		world.setBlockMetadataWithNotify(i + 2, j + 5, k + 25, 5, 2);
		this.setBlock(world, i + 2, j + 5, k + 26, Blocks.planks, 0);
		world.setBlockMetadataWithNotify(i + 2, j + 5, k + 26, 5, 2);
		this.setBlock(world, i + 2, j + 5, k + 27, Blocks.planks, 0);
		world.setBlockMetadataWithNotify(i + 2, j + 5, k + 27, 5, 2);
		this.setBlock(world, i + 2, j + 5, k + 28, Blocks.planks, 0);
		world.setBlockMetadataWithNotify(i + 2, j + 5, k + 28, 5, 2);
		this.setBlock(world, i + 2, j + 5, k + 29, Blocks.planks, 0);
		world.setBlockMetadataWithNotify(i + 2, j + 5, k + 29, 5, 2);
		this.setBlock(world, i + 2, j + 5, k + 30, Blocks.planks, 0);
		world.setBlockMetadataWithNotify(i + 2, j + 5, k + 30, 5, 2);
		this.setBlock(world, i + 2, j + 5, k + 31, Blocks.planks, 0);
		world.setBlockMetadataWithNotify(i + 2, j + 5, k + 31, 5, 2);
		this.setBlock(world, i + 2, j + 5, k + 32, Blocks.air, 0);
		this.setBlock(world, i + 2, j + 5, k + 33, Blocks.air, 0);
		this.setBlock(world, i + 2, j + 5, k + 34, Blocks.air, 0);
		this.setBlock(world, i + 2, j + 6, k + 0, Blocks.air, 0);
		this.setBlock(world, i + 2, j + 6, k + 1, Blocks.air, 0);
		this.setBlock(world, i + 2, j + 6, k + 2, Blocks.air, 0);
		this.setBlock(world, i + 2, j + 6, k + 3, Blocks.air, 0);
		this.setBlock(world, i + 2, j + 6, k + 4, Blocks.air, 0);
		this.setBlock(world, i + 2, j + 6, k + 5, Blocks.air, 0);
		this.setBlock(world, i + 2, j + 6, k + 6, Blocks.air, 0);
		this.setBlock(world, i + 2, j + 6, k + 7, Blocks.air, 0);
		this.setBlock(world, i + 2, j + 6, k + 8, Blocks.air, 0);
		this.setBlock(world, i + 2, j + 6, k + 9, Blocks.air, 0);
		this.setBlock(world, i + 2, j + 6, k + 10, Blocks.air, 0);
		this.setBlock(world, i + 2, j + 6, k + 11, Blocks.air, 0);
		this.setBlock(world, i + 2, j + 6, k + 12, Blocks.air, 0);
		this.setBlock(world, i + 2, j + 6, k + 13, Blocks.air, 0);
		this.setBlock(world, i + 2, j + 6, k + 14, Blocks.air, 0);
		this.setBlock(world, i + 2, j + 6, k + 15, Blocks.air, 0);
		this.setBlock(world, i + 2, j + 6, k + 16, Blocks.air, 0);
		this.setBlock(world, i + 2, j + 6, k + 17, Blocks.air, 0);
		this.setBlock(world, i + 2, j + 6, k + 18, Blocks.air, 0);
		this.setBlock(world, i + 2, j + 6, k + 19, Blocks.air, 0);
		this.setBlock(world, i + 2, j + 6, k + 20, Blocks.air, 0);
		this.setBlock(world, i + 2, j + 6, k + 21, Blocks.air, 0);
		this.setBlock(world, i + 2, j + 6, k + 22, Blocks.air, 0);
		this.setBlock(world, i + 2, j + 6, k + 23, Blocks.air, 0);
		this.setBlock(world, i + 2, j + 6, k + 24, Blocks.air, 0);
		this.setBlock(world, i + 2, j + 6, k + 25, Blocks.air, 0);
		this.setBlock(world, i + 2, j + 6, k + 26, Blocks.air, 0);
		this.setBlock(world, i + 2, j + 6, k + 27, Blocks.air, 0);
		this.setBlock(world, i + 2, j + 6, k + 28, Blocks.air, 0);
		this.setBlock(world, i + 2, j + 6, k + 29, Blocks.air, 0);
		this.setBlock(world, i + 2, j + 6, k + 30, Blocks.air, 0);
		this.setBlock(world, i + 2, j + 6, k + 31, Blocks.air, 0);
		this.setBlock(world, i + 2, j + 6, k + 32, Blocks.air, 0);
		this.setBlock(world, i + 2, j + 6, k + 33, Blocks.air, 0);
		this.setBlock(world, i + 2, j + 6, k + 34, Blocks.air, 0);
		this.setBlock(world, i + 2, j + 7, k + 0, Blocks.air, 0);
		this.setBlock(world, i + 2, j + 7, k + 1, Blocks.air, 0);
		this.setBlock(world, i + 2, j + 7, k + 2, Blocks.air, 0);
		this.setBlock(world, i + 2, j + 7, k + 3, Blocks.air, 0);
		this.setBlock(world, i + 2, j + 7, k + 4, Blocks.air, 0);
		this.setBlock(world, i + 2, j + 7, k + 5, Blocks.air, 0);
		this.setBlock(world, i + 2, j + 7, k + 6, Blocks.air, 0);
		this.setBlock(world, i + 2, j + 7, k + 7, Blocks.air, 0);
		this.setBlock(world, i + 2, j + 7, k + 8, Blocks.air, 0);
		this.setBlock(world, i + 2, j + 7, k + 9, Blocks.air, 0);
		this.setBlock(world, i + 2, j + 7, k + 10, Blocks.air, 0);
		this.setBlock(world, i + 2, j + 7, k + 11, Blocks.air, 0);
		this.setBlock(world, i + 2, j + 7, k + 12, Blocks.air, 0);
		this.setBlock(world, i + 2, j + 7, k + 13, Blocks.air, 0);
		this.setBlock(world, i + 2, j + 7, k + 14, Blocks.air, 0);
		this.setBlock(world, i + 2, j + 7, k + 15, Blocks.air, 0);
		this.setBlock(world, i + 2, j + 7, k + 16, Blocks.air, 0);
		this.setBlock(world, i + 2, j + 7, k + 17, Blocks.air, 0);
		this.setBlock(world, i + 2, j + 7, k + 18, Blocks.air, 0);
		this.setBlock(world, i + 2, j + 7, k + 19, Blocks.air, 0);
		this.setBlock(world, i + 2, j + 7, k + 20, Blocks.air, 0);
		this.setBlock(world, i + 2, j + 7, k + 21, Blocks.air, 0);
		this.setBlock(world, i + 2, j + 7, k + 22, Blocks.air, 0);
		this.setBlock(world, i + 2, j + 7, k + 23, Blocks.air, 0);
		this.setBlock(world, i + 2, j + 7, k + 24, Blocks.air, 0);
		this.setBlock(world, i + 2, j + 7, k + 25, Blocks.air, 0);
		this.setBlock(world, i + 2, j + 7, k + 26, Blocks.air, 0);
		this.setBlock(world, i + 2, j + 7, k + 27, Blocks.air, 0);
		this.setBlock(world, i + 2, j + 7, k + 28, Blocks.air, 0);
		this.setBlock(world, i + 2, j + 7, k + 29, Blocks.air, 0);
		this.setBlock(world, i + 2, j + 7, k + 30, Blocks.air, 0);
		this.setBlock(world, i + 2, j + 7, k + 31, Blocks.air, 0);
		this.setBlock(world, i + 2, j + 7, k + 32, Blocks.air, 0);
		this.setBlock(world, i + 2, j + 7, k + 33, Blocks.air, 0);
		this.setBlock(world, i + 2, j + 7, k + 34, Blocks.air, 0);
		this.setBlock(world, i + 3, j + 0, k + 0, Blocks.grass, 0);
		this.setBlock(world, i + 3, j + 0, k + 1, Blocks.grass, 0);
		this.setBlock(world, i + 3, j + 0, k + 2, Blocks.grass, 0);
		this.setBlock(world, i + 3, j + 0, k + 3, Blocks.grass, 0);
		this.setBlock(world, i + 3, j + 0, k + 4, Blocks.grass, 0);
		this.setBlock(world, i + 3, j + 0, k + 5, Blocks.grass, 0);
		this.setBlock(world, i + 3, j + 0, k + 6, Blocks.grass, 0);
		this.setBlock(world, i + 3, j + 0, k + 7, Blocks.quartz_block, 0);
		this.setBlock(world, i + 3, j + 0, k + 8, Blocks.quartz_block, 0);
		this.setBlock(world, i + 3, j + 0, k + 9, Blocks.quartz_block, 0);
		this.setBlock(world, i + 3, j + 0, k + 10, Blocks.quartz_block, 0);
		this.setBlock(world, i + 3, j + 0, k + 11, Blocks.quartz_block, 0);
		this.setBlock(world, i + 3, j + 0, k + 12, Blocks.quartz_block, 0);
		this.setBlock(world, i + 3, j + 0, k + 13, Blocks.quartz_block, 0);
		this.setBlock(world, i + 3, j + 0, k + 14, Blocks.quartz_block, 0);
		this.setBlock(world, i + 3, j + 0, k + 15, Blocks.quartz_block, 0);
		this.setBlock(world, i + 3, j + 0, k + 16, Blocks.quartz_block, 0);
		this.setBlock(world, i + 3, j + 0, k + 17, Blocks.quartz_block, 0);
		this.setBlock(world, i + 3, j + 0, k + 18, Blocks.quartz_block, 0);
		this.setBlock(world, i + 3, j + 0, k + 19, Blocks.quartz_block, 0);
		this.setBlock(world, i + 3, j + 0, k + 20, Blocks.quartz_block, 0);
		this.setBlock(world, i + 3, j + 0, k + 21, Blocks.quartz_block, 0);
		this.setBlock(world, i + 3, j + 0, k + 22, Blocks.quartz_block, 0);
		this.setBlock(world, i + 3, j + 0, k + 23, Blocks.quartz_block, 0);
		this.setBlock(world, i + 3, j + 0, k + 24, Blocks.quartz_block, 0);
		this.setBlock(world, i + 3, j + 0, k + 25, Blocks.quartz_block, 0);
		this.setBlock(world, i + 3, j + 0, k + 26, Blocks.quartz_block, 0);
		this.setBlock(world, i + 3, j + 0, k + 27, Blocks.quartz_block, 0);
		this.setBlock(world, i + 3, j + 0, k + 28, Blocks.grass, 0);
		this.setBlock(world, i + 3, j + 0, k + 29, Blocks.grass, 0);
		this.setBlock(world, i + 3, j + 0, k + 30, Blocks.grass, 0);
		this.setBlock(world, i + 3, j + 0, k + 31, Blocks.grass, 0);
		this.setBlock(world, i + 3, j + 0, k + 32, Blocks.grass, 0);
		this.setBlock(world, i + 3, j + 0, k + 33, Blocks.grass, 0);
		this.setBlock(world, i + 3, j + 0, k + 34, Blocks.grass, 0);
		this.setBlock(world, i + 3, j + 1, k + 0, Blocks.air, 0);
		this.setBlock(world, i + 3, j + 1, k + 1, Blocks.air, 0);
		this.setBlock(world, i + 3, j + 1, k + 2, Blocks.air, 0);
		this.setBlock(world, i + 3, j + 1, k + 3, Blocks.air, 0);
		this.setBlock(world, i + 3, j + 1, k + 4, StarWarsMod.blockEndorBaseWall, 0);
		world.setBlockMetadataWithNotify(i + 3, j + 1, k + 4, 1, 2);
		this.setBlock(world, i + 3, j + 1, k + 5, Blocks.planks, 0);
		world.setBlockMetadataWithNotify(i + 3, j + 1, k + 5, 5, 2);
		this.setBlock(world, i + 3, j + 1, k + 6, StarWarsMod.blockEndorBaseWall, 0);
		world.setBlockMetadataWithNotify(i + 3, j + 1, k + 6, 1, 2);
		this.setBlock(world, i + 3, j + 1, k + 7, Blocks.air, 0);
		this.setBlock(world, i + 3, j + 1, k + 8, Blocks.air, 0);
		this.setBlock(world, i + 3, j + 1, k + 9, Blocks.air, 0);
		this.setBlock(world, i + 3, j + 1, k + 10, StarWarsMod.blockEndorBaseWall, 0);
		world.setBlockMetadataWithNotify(i + 3, j + 1, k + 10, 1, 2);
		this.setBlock(world, i + 3, j + 1, k + 11, StarWarsMod.blockEndorBaseWall, 0);
		world.setBlockMetadataWithNotify(i + 3, j + 1, k + 11, 1, 2);
		this.setBlock(world, i + 3, j + 1, k + 12, StarWarsMod.blockEndorBaseWall, 0);
		world.setBlockMetadataWithNotify(i + 3, j + 1, k + 12, 1, 2);
		this.setBlock(world, i + 3, j + 1, k + 13, StarWarsMod.blockEndorBaseWall, 0);
		world.setBlockMetadataWithNotify(i + 3, j + 1, k + 13, 1, 2);
		this.setBlock(world, i + 3, j + 1, k + 14, StarWarsMod.blockEndorBaseWall, 0);
		world.setBlockMetadataWithNotify(i + 3, j + 1, k + 14, 1, 2);
		this.setBlock(world, i + 3, j + 1, k + 15, Blocks.chest, 0);
		world.setBlockMetadataWithNotify(i + 3, j + 1, k + 15, 5, 2);
		this.setBlock(world, i + 3, j + 1, k + 16, StarWarsMod.blockEndorBaseWall, 0);
		world.setBlockMetadataWithNotify(i + 3, j + 1, k + 16, 1, 2);
		this.setBlock(world, i + 3, j + 1, k + 17, StarWarsMod.blockEndorBaseWall, 0);
		world.setBlockMetadataWithNotify(i + 3, j + 1, k + 17, 1, 2);
		this.setBlock(world, i + 3, j + 1, k + 18, StarWarsMod.blockEndorBaseWall, 0);
		world.setBlockMetadataWithNotify(i + 3, j + 1, k + 18, 1, 2);
		this.setBlock(world, i + 3, j + 1, k + 19, Blocks.chest, 0);
		world.setBlockMetadataWithNotify(i + 3, j + 1, k + 19, 5, 2);
		this.setBlock(world, i + 3, j + 1, k + 20, StarWarsMod.blockEndorBaseWall, 0);
		world.setBlockMetadataWithNotify(i + 3, j + 1, k + 20, 1, 2);
		this.setBlock(world, i + 3, j + 1, k + 21, StarWarsMod.blockEndorBaseWall, 0);
		world.setBlockMetadataWithNotify(i + 3, j + 1, k + 21, 1, 2);
		this.setBlock(world, i + 3, j + 1, k + 22, StarWarsMod.blockEndorBaseWall, 0);
		world.setBlockMetadataWithNotify(i + 3, j + 1, k + 22, 1, 2);
		this.setBlock(world, i + 3, j + 1, k + 23, StarWarsMod.blockEndorBaseWall, 0);
		world.setBlockMetadataWithNotify(i + 3, j + 1, k + 23, 1, 2);
		this.setBlock(world, i + 3, j + 1, k + 24, StarWarsMod.blockEndorBaseWall, 0);
		world.setBlockMetadataWithNotify(i + 3, j + 1, k + 24, 1, 2);
		this.setBlock(world, i + 3, j + 1, k + 25, Blocks.air, 0);
		this.setBlock(world, i + 3, j + 1, k + 26, Blocks.air, 0);
		this.setBlock(world, i + 3, j + 1, k + 27, Blocks.air, 0);
		this.setBlock(world, i + 3, j + 1, k + 28, StarWarsMod.blockEndorBaseWall, 0);
		world.setBlockMetadataWithNotify(i + 3, j + 1, k + 28, 1, 2);
		this.setBlock(world, i + 3, j + 1, k + 29, Blocks.planks, 0);
		world.setBlockMetadataWithNotify(i + 3, j + 1, k + 29, 5, 2);
		this.setBlock(world, i + 3, j + 1, k + 30, StarWarsMod.blockEndorBaseWall, 0);
		world.setBlockMetadataWithNotify(i + 3, j + 1, k + 30, 1, 2);
		this.setBlock(world, i + 3, j + 1, k + 31, Blocks.air, 0);
		this.setBlock(world, i + 3, j + 1, k + 32, Blocks.air, 0);
		this.setBlock(world, i + 3, j + 1, k + 33, Blocks.air, 0);
		this.setBlock(world, i + 3, j + 1, k + 34, Blocks.air, 0);
		this.setBlock(world, i + 3, j + 2, k + 0, Blocks.air, 0);
		this.setBlock(world, i + 3, j + 2, k + 1, Blocks.air, 0);
		this.setBlock(world, i + 3, j + 2, k + 2, Blocks.air, 0);
		this.setBlock(world, i + 3, j + 2, k + 3, Blocks.air, 0);
		this.setBlock(world, i + 3, j + 2, k + 4, StarWarsMod.blockEndorBaseWall, 0);
		world.setBlockMetadataWithNotify(i + 3, j + 2, k + 4, 1, 2);
		this.setBlock(world, i + 3, j + 2, k + 5, Blocks.planks, 0);
		world.setBlockMetadataWithNotify(i + 3, j + 2, k + 5, 5, 2);
		this.setBlock(world, i + 3, j + 2, k + 6, StarWarsMod.blockEndorBaseWall, 0);
		world.setBlockMetadataWithNotify(i + 3, j + 2, k + 6, 1, 2);
		this.setBlock(world, i + 3, j + 2, k + 7, Blocks.air, 0);
		this.setBlock(world, i + 3, j + 2, k + 8, Blocks.air, 0);
		this.setBlock(world, i + 3, j + 2, k + 9, Blocks.air, 0);
		this.setBlock(world, i + 3, j + 2, k + 10, Blocks.air, 0);
		this.setBlock(world, i + 3, j + 2, k + 11, Blocks.air, 0);
		this.setBlock(world, i + 3, j + 2, k + 12, StarWarsMod.blockEndorBaseWall, 0);
		world.setBlockMetadataWithNotify(i + 3, j + 2, k + 12, 1, 2);
		this.setBlock(world, i + 3, j + 2, k + 13, Blocks.stained_glass_pane, 0);
		world.setBlockMetadataWithNotify(i + 3, j + 2, k + 13, 8, 2);
		this.setBlock(world, i + 3, j + 2, k + 14, Blocks.air, 0);
		this.setBlock(world, i + 3, j + 2, k + 15, Blocks.air, 0);
		this.setBlock(world, i + 3, j + 2, k + 16, Blocks.air, 0);
		this.setBlock(world, i + 3, j + 2, k + 17, Blocks.air, 0);
		this.setBlock(world, i + 3, j + 2, k + 18, Blocks.air, 0);
		this.setBlock(world, i + 3, j + 2, k + 19, Blocks.air, 0);
		this.setBlock(world, i + 3, j + 2, k + 20, Blocks.air, 0);
		this.setBlock(world, i + 3, j + 2, k + 21, Blocks.stained_glass_pane, 0);
		world.setBlockMetadataWithNotify(i + 3, j + 2, k + 21, 8, 2);
		this.setBlock(world, i + 3, j + 2, k + 22, StarWarsMod.blockEndorBaseWall, 0);
		world.setBlockMetadataWithNotify(i + 3, j + 2, k + 22, 1, 2);
		this.setBlock(world, i + 3, j + 2, k + 23, Blocks.air, 0);
		this.setBlock(world, i + 3, j + 2, k + 24, Blocks.air, 0);
		this.setBlock(world, i + 3, j + 2, k + 25, Blocks.air, 0);
		this.setBlock(world, i + 3, j + 2, k + 26, Blocks.air, 0);
		this.setBlock(world, i + 3, j + 2, k + 27, Blocks.air, 0);
		this.setBlock(world, i + 3, j + 2, k + 28, StarWarsMod.blockEndorBaseWall, 0);
		world.setBlockMetadataWithNotify(i + 3, j + 2, k + 28, 1, 2);
		this.setBlock(world, i + 3, j + 2, k + 29, Blocks.planks, 0);
		world.setBlockMetadataWithNotify(i + 3, j + 2, k + 29, 5, 2);
		this.setBlock(world, i + 3, j + 2, k + 30, StarWarsMod.blockEndorBaseWall, 0);
		world.setBlockMetadataWithNotify(i + 3, j + 2, k + 30, 1, 2);
		this.setBlock(world, i + 3, j + 2, k + 31, Blocks.air, 0);
		this.setBlock(world, i + 3, j + 2, k + 32, Blocks.air, 0);
		this.setBlock(world, i + 3, j + 2, k + 33, Blocks.air, 0);
		this.setBlock(world, i + 3, j + 2, k + 34, Blocks.air, 0);
		this.setBlock(world, i + 3, j + 3, k + 0, Blocks.air, 0);
		this.setBlock(world, i + 3, j + 3, k + 1, Blocks.air, 0);
		this.setBlock(world, i + 3, j + 3, k + 2, Blocks.air, 0);
		this.setBlock(world, i + 3, j + 3, k + 3, Blocks.air, 0);
		this.setBlock(world, i + 3, j + 3, k + 4, StarWarsMod.blockEndorBaseWall, 0);
		world.setBlockMetadataWithNotify(i + 3, j + 3, k + 4, 1, 2);
		this.setBlock(world, i + 3, j + 3, k + 5, Blocks.planks, 0);
		world.setBlockMetadataWithNotify(i + 3, j + 3, k + 5, 5, 2);
		this.setBlock(world, i + 3, j + 3, k + 6, StarWarsMod.blockEndorBaseWall, 0);
		world.setBlockMetadataWithNotify(i + 3, j + 3, k + 6, 1, 2);
		this.setBlock(world, i + 3, j + 3, k + 7, Blocks.air, 0);
		this.setBlock(world, i + 3, j + 3, k + 8, Blocks.air, 0);
		this.setBlock(world, i + 3, j + 3, k + 9, Blocks.air, 0);
		this.setBlock(world, i + 3, j + 3, k + 10, Blocks.air, 0);
		this.setBlock(world, i + 3, j + 3, k + 11, Blocks.air, 0);
		this.setBlock(world, i + 3, j + 3, k + 12, StarWarsMod.blockEndorBaseWall, 0);
		world.setBlockMetadataWithNotify(i + 3, j + 3, k + 12, 1, 2);
		this.setBlock(world, i + 3, j + 3, k + 13, Blocks.stained_glass_pane, 0);
		world.setBlockMetadataWithNotify(i + 3, j + 3, k + 13, 8, 2);
		this.setBlock(world, i + 3, j + 3, k + 14, Blocks.air, 0);
		this.setBlock(world, i + 3, j + 3, k + 15, Blocks.air, 0);
		this.setBlock(world, i + 3, j + 3, k + 16, Blocks.air, 0);
		this.setBlock(world, i + 3, j + 3, k + 17, Blocks.air, 0);
		this.setBlock(world, i + 3, j + 3, k + 18, Blocks.air, 0);
		this.setBlock(world, i + 3, j + 3, k + 19, Blocks.air, 0);
		this.setBlock(world, i + 3, j + 3, k + 20, Blocks.air, 0);
		this.setBlock(world, i + 3, j + 3, k + 21, Blocks.stained_glass_pane, 0);
		world.setBlockMetadataWithNotify(i + 3, j + 3, k + 21, 8, 2);
		this.setBlock(world, i + 3, j + 3, k + 22, StarWarsMod.blockEndorBaseWall, 0);
		world.setBlockMetadataWithNotify(i + 3, j + 3, k + 22, 1, 2);
		this.setBlock(world, i + 3, j + 3, k + 23, Blocks.air, 0);
		this.setBlock(world, i + 3, j + 3, k + 24, Blocks.air, 0);
		this.setBlock(world, i + 3, j + 3, k + 25, Blocks.air, 0);
		this.setBlock(world, i + 3, j + 3, k + 26, Blocks.air, 0);
		this.setBlock(world, i + 3, j + 3, k + 27, Blocks.air, 0);
		this.setBlock(world, i + 3, j + 3, k + 28, StarWarsMod.blockEndorBaseWall, 0);
		world.setBlockMetadataWithNotify(i + 3, j + 3, k + 28, 1, 2);
		this.setBlock(world, i + 3, j + 3, k + 29, Blocks.planks, 0);
		world.setBlockMetadataWithNotify(i + 3, j + 3, k + 29, 5, 2);
		this.setBlock(world, i + 3, j + 3, k + 30, StarWarsMod.blockEndorBaseWall, 0);
		world.setBlockMetadataWithNotify(i + 3, j + 3, k + 30, 1, 2);
		this.setBlock(world, i + 3, j + 3, k + 31, Blocks.air, 0);
		this.setBlock(world, i + 3, j + 3, k + 32, Blocks.air, 0);
		this.setBlock(world, i + 3, j + 3, k + 33, Blocks.air, 0);
		this.setBlock(world, i + 3, j + 3, k + 34, Blocks.air, 0);
		this.setBlock(world, i + 3, j + 4, k + 0, Blocks.air, 0);
		this.setBlock(world, i + 3, j + 4, k + 1, Blocks.air, 0);
		this.setBlock(world, i + 3, j + 4, k + 2, Blocks.air, 0);
		this.setBlock(world, i + 3, j + 4, k + 3, Blocks.air, 0);
		this.setBlock(world, i + 3, j + 4, k + 4, StarWarsMod.blockEndorBaseWall, 0);
		world.setBlockMetadataWithNotify(i + 3, j + 4, k + 4, 1, 2);
		this.setBlock(world, i + 3, j + 4, k + 5, Blocks.planks, 0);
		world.setBlockMetadataWithNotify(i + 3, j + 4, k + 5, 5, 2);
		this.setBlock(world, i + 3, j + 4, k + 6, StarWarsMod.blockEndorBaseWall, 0);
		world.setBlockMetadataWithNotify(i + 3, j + 4, k + 6, 1, 2);
		this.setBlock(world, i + 3, j + 4, k + 7, Blocks.air, 0);
		this.setBlock(world, i + 3, j + 4, k + 8, Blocks.air, 0);
		this.setBlock(world, i + 3, j + 4, k + 9, Blocks.air, 0);
		this.setBlock(world, i + 3, j + 4, k + 10, StarWarsMod.blockEndorBaseWall, 0);
		world.setBlockMetadataWithNotify(i + 3, j + 4, k + 10, 1, 2);
		this.setBlock(world, i + 3, j + 4, k + 11, StarWarsMod.blockEndorBaseWall, 0);
		world.setBlockMetadataWithNotify(i + 3, j + 4, k + 11, 1, 2);
		this.setBlock(world, i + 3, j + 4, k + 12, StarWarsMod.blockEndorBaseWall, 0);
		world.setBlockMetadataWithNotify(i + 3, j + 4, k + 12, 1, 2);
		this.setBlock(world, i + 3, j + 4, k + 13, StarWarsMod.blockEndorBaseWall, 0);
		world.setBlockMetadataWithNotify(i + 3, j + 4, k + 13, 1, 2);
		this.setBlock(world, i + 3, j + 4, k + 14, StarWarsMod.blockEndorBaseWall, 0);
		world.setBlockMetadataWithNotify(i + 3, j + 4, k + 14, 1, 2);
		this.setBlock(world, i + 3, j + 4, k + 15, Blocks.air, 0);
		this.setBlock(world, i + 3, j + 4, k + 16, StarWarsMod.blockEndorBaseWall, 0);
		world.setBlockMetadataWithNotify(i + 3, j + 4, k + 16, 1, 2);
		this.setBlock(world, i + 3, j + 4, k + 17, StarWarsMod.blockEndorBaseWall, 0);
		world.setBlockMetadataWithNotify(i + 3, j + 4, k + 17, 1, 2);
		this.setBlock(world, i + 3, j + 4, k + 18, StarWarsMod.blockEndorBaseWall, 0);
		world.setBlockMetadataWithNotify(i + 3, j + 4, k + 18, 1, 2);
		this.setBlock(world, i + 3, j + 4, k + 19, Blocks.air, 0);
		this.setBlock(world, i + 3, j + 4, k + 20, StarWarsMod.blockEndorBaseWall, 0);
		world.setBlockMetadataWithNotify(i + 3, j + 4, k + 20, 1, 2);
		this.setBlock(world, i + 3, j + 4, k + 21, StarWarsMod.blockEndorBaseWall, 0);
		world.setBlockMetadataWithNotify(i + 3, j + 4, k + 21, 1, 2);
		generate_2(world, rand, i, j, k);
		return true;
	}

	public boolean generate_2(World world, Random rand, int i, int j, int k)
	{
		this.setBlock(world, i + 3, j + 4, k + 22, StarWarsMod.blockEndorBaseWall, 0);
		world.setBlockMetadataWithNotify(i + 3, j + 4, k + 22, 1, 2);
		this.setBlock(world, i + 3, j + 4, k + 23, StarWarsMod.blockEndorBaseWall, 0);
		world.setBlockMetadataWithNotify(i + 3, j + 4, k + 23, 1, 2);
		this.setBlock(world, i + 3, j + 4, k + 24, StarWarsMod.blockEndorBaseWall, 0);
		world.setBlockMetadataWithNotify(i + 3, j + 4, k + 24, 1, 2);
		this.setBlock(world, i + 3, j + 4, k + 25, Blocks.air, 0);
		this.setBlock(world, i + 3, j + 4, k + 26, Blocks.air, 0);
		this.setBlock(world, i + 3, j + 4, k + 27, Blocks.air, 0);
		this.setBlock(world, i + 3, j + 4, k + 28, StarWarsMod.blockEndorBaseWall, 0);
		world.setBlockMetadataWithNotify(i + 3, j + 4, k + 28, 1, 2);
		this.setBlock(world, i + 3, j + 4, k + 29, Blocks.planks, 0);
		world.setBlockMetadataWithNotify(i + 3, j + 4, k + 29, 5, 2);
		this.setBlock(world, i + 3, j + 4, k + 30, StarWarsMod.blockEndorBaseWall, 0);
		world.setBlockMetadataWithNotify(i + 3, j + 4, k + 30, 1, 2);
		this.setBlock(world, i + 3, j + 4, k + 31, Blocks.air, 0);
		this.setBlock(world, i + 3, j + 4, k + 32, Blocks.air, 0);
		this.setBlock(world, i + 3, j + 4, k + 33, Blocks.air, 0);
		this.setBlock(world, i + 3, j + 4, k + 34, Blocks.air, 0);
		this.setBlock(world, i + 3, j + 5, k + 0, Blocks.air, 0);
		this.setBlock(world, i + 3, j + 5, k + 1, Blocks.air, 0);
		this.setBlock(world, i + 3, j + 5, k + 2, Blocks.planks, 0);
		world.setBlockMetadataWithNotify(i + 3, j + 5, k + 2, 5, 2);
		this.setBlock(world, i + 3, j + 5, k + 3, Blocks.planks, 0);
		world.setBlockMetadataWithNotify(i + 3, j + 5, k + 3, 5, 2);
		this.setBlock(world, i + 3, j + 5, k + 4, Blocks.planks, 0);
		world.setBlockMetadataWithNotify(i + 3, j + 5, k + 4, 5, 2);
		this.setBlock(world, i + 3, j + 5, k + 5, Blocks.planks, 0);
		world.setBlockMetadataWithNotify(i + 3, j + 5, k + 5, 5, 2);
		this.setBlock(world, i + 3, j + 5, k + 6, Blocks.planks, 0);
		world.setBlockMetadataWithNotify(i + 3, j + 5, k + 6, 5, 2);
		this.setBlock(world, i + 3, j + 5, k + 7, Blocks.planks, 0);
		world.setBlockMetadataWithNotify(i + 3, j + 5, k + 7, 5, 2);
		this.setBlock(world, i + 3, j + 5, k + 8, Blocks.planks, 0);
		world.setBlockMetadataWithNotify(i + 3, j + 5, k + 8, 5, 2);
		this.setBlock(world, i + 3, j + 5, k + 9, Blocks.planks, 0);
		world.setBlockMetadataWithNotify(i + 3, j + 5, k + 9, 5, 2);
		this.setBlock(world, i + 3, j + 5, k + 10, Blocks.planks, 0);
		world.setBlockMetadataWithNotify(i + 3, j + 5, k + 10, 5, 2);
		this.setBlock(world, i + 3, j + 5, k + 11, Blocks.planks, 0);
		world.setBlockMetadataWithNotify(i + 3, j + 5, k + 11, 5, 2);
		this.setBlock(world, i + 3, j + 5, k + 12, Blocks.planks, 0);
		world.setBlockMetadataWithNotify(i + 3, j + 5, k + 12, 5, 2);
		this.setBlock(world, i + 3, j + 5, k + 13, Blocks.planks, 0);
		world.setBlockMetadataWithNotify(i + 3, j + 5, k + 13, 5, 2);
		this.setBlock(world, i + 3, j + 5, k + 14, Blocks.planks, 0);
		world.setBlockMetadataWithNotify(i + 3, j + 5, k + 14, 5, 2);
		this.setBlock(world, i + 3, j + 5, k + 15, Blocks.planks, 0);
		world.setBlockMetadataWithNotify(i + 3, j + 5, k + 15, 5, 2);
		this.setBlock(world, i + 3, j + 5, k + 16, Blocks.planks, 0);
		world.setBlockMetadataWithNotify(i + 3, j + 5, k + 16, 5, 2);
		this.setBlock(world, i + 3, j + 5, k + 17, Blocks.planks, 0);
		world.setBlockMetadataWithNotify(i + 3, j + 5, k + 17, 5, 2);
		this.setBlock(world, i + 3, j + 5, k + 18, Blocks.planks, 0);
		world.setBlockMetadataWithNotify(i + 3, j + 5, k + 18, 5, 2);
		this.setBlock(world, i + 3, j + 5, k + 19, Blocks.planks, 0);
		world.setBlockMetadataWithNotify(i + 3, j + 5, k + 19, 5, 2);
		this.setBlock(world, i + 3, j + 5, k + 20, Blocks.planks, 0);
		world.setBlockMetadataWithNotify(i + 3, j + 5, k + 20, 5, 2);
		this.setBlock(world, i + 3, j + 5, k + 21, Blocks.planks, 0);
		world.setBlockMetadataWithNotify(i + 3, j + 5, k + 21, 5, 2);
		this.setBlock(world, i + 3, j + 5, k + 22, Blocks.planks, 0);
		world.setBlockMetadataWithNotify(i + 3, j + 5, k + 22, 5, 2);
		this.setBlock(world, i + 3, j + 5, k + 23, Blocks.planks, 0);
		world.setBlockMetadataWithNotify(i + 3, j + 5, k + 23, 5, 2);
		this.setBlock(world, i + 3, j + 5, k + 24, Blocks.planks, 0);
		world.setBlockMetadataWithNotify(i + 3, j + 5, k + 24, 5, 2);
		this.setBlock(world, i + 3, j + 5, k + 25, Blocks.planks, 0);
		world.setBlockMetadataWithNotify(i + 3, j + 5, k + 25, 5, 2);
		this.setBlock(world, i + 3, j + 5, k + 26, Blocks.planks, 0);
		world.setBlockMetadataWithNotify(i + 3, j + 5, k + 26, 5, 2);
		this.setBlock(world, i + 3, j + 5, k + 27, Blocks.planks, 0);
		world.setBlockMetadataWithNotify(i + 3, j + 5, k + 27, 5, 2);
		this.setBlock(world, i + 3, j + 5, k + 28, Blocks.planks, 0);
		world.setBlockMetadataWithNotify(i + 3, j + 5, k + 28, 5, 2);
		this.setBlock(world, i + 3, j + 5, k + 29, Blocks.planks, 0);
		world.setBlockMetadataWithNotify(i + 3, j + 5, k + 29, 5, 2);
		this.setBlock(world, i + 3, j + 5, k + 30, Blocks.planks, 0);
		world.setBlockMetadataWithNotify(i + 3, j + 5, k + 30, 5, 2);
		this.setBlock(world, i + 3, j + 5, k + 31, Blocks.planks, 0);
		world.setBlockMetadataWithNotify(i + 3, j + 5, k + 31, 5, 2);
		this.setBlock(world, i + 3, j + 5, k + 32, Blocks.planks, 0);
		world.setBlockMetadataWithNotify(i + 3, j + 5, k + 32, 5, 2);
		this.setBlock(world, i + 3, j + 5, k + 33, Blocks.air, 0);
		this.setBlock(world, i + 3, j + 5, k + 34, Blocks.air, 0);
		this.setBlock(world, i + 3, j + 6, k + 0, Blocks.air, 0);
		this.setBlock(world, i + 3, j + 6, k + 1, Blocks.air, 0);
		this.setBlock(world, i + 3, j + 6, k + 2, Blocks.air, 0);
		this.setBlock(world, i + 3, j + 6, k + 3, Blocks.air, 0);
		this.setBlock(world, i + 3, j + 6, k + 4, Blocks.air, 0);
		this.setBlock(world, i + 3, j + 6, k + 5, Blocks.air, 0);
		this.setBlock(world, i + 3, j + 6, k + 6, Blocks.air, 0);
		this.setBlock(world, i + 3, j + 6, k + 7, Blocks.air, 0);
		this.setBlock(world, i + 3, j + 6, k + 8, Blocks.air, 0);
		this.setBlock(world, i + 3, j + 6, k + 9, Blocks.air, 0);
		this.setBlock(world, i + 3, j + 6, k + 10, Blocks.air, 0);
		this.setBlock(world, i + 3, j + 6, k + 11, Blocks.air, 0);
		this.setBlock(world, i + 3, j + 6, k + 12, Blocks.air, 0);
		this.setBlock(world, i + 3, j + 6, k + 13, Blocks.air, 0);
		this.setBlock(world, i + 3, j + 6, k + 14, Blocks.air, 0);
		this.setBlock(world, i + 3, j + 6, k + 15, Blocks.air, 0);
		this.setBlock(world, i + 3, j + 6, k + 16, Blocks.air, 0);
		this.setBlock(world, i + 3, j + 6, k + 17, Blocks.air, 0);
		this.setBlock(world, i + 3, j + 6, k + 18, Blocks.air, 0);
		this.setBlock(world, i + 3, j + 6, k + 19, Blocks.air, 0);
		this.setBlock(world, i + 3, j + 6, k + 20, Blocks.air, 0);
		this.setBlock(world, i + 3, j + 6, k + 21, Blocks.air, 0);
		this.setBlock(world, i + 3, j + 6, k + 22, Blocks.air, 0);
		this.setBlock(world, i + 3, j + 6, k + 23, Blocks.air, 0);
		this.setBlock(world, i + 3, j + 6, k + 24, Blocks.air, 0);
		this.setBlock(world, i + 3, j + 6, k + 25, Blocks.air, 0);
		this.setBlock(world, i + 3, j + 6, k + 26, Blocks.air, 0);
		this.setBlock(world, i + 3, j + 6, k + 27, Blocks.air, 0);
		this.setBlock(world, i + 3, j + 6, k + 28, Blocks.air, 0);
		this.setBlock(world, i + 3, j + 6, k + 29, Blocks.air, 0);
		this.setBlock(world, i + 3, j + 6, k + 30, Blocks.air, 0);
		this.setBlock(world, i + 3, j + 6, k + 31, Blocks.air, 0);
		this.setBlock(world, i + 3, j + 6, k + 32, Blocks.air, 0);
		this.setBlock(world, i + 3, j + 6, k + 33, Blocks.air, 0);
		this.setBlock(world, i + 3, j + 6, k + 34, Blocks.air, 0);
		this.setBlock(world, i + 3, j + 7, k + 0, Blocks.air, 0);
		this.setBlock(world, i + 3, j + 7, k + 1, Blocks.air, 0);
		this.setBlock(world, i + 3, j + 7, k + 2, Blocks.air, 0);
		this.setBlock(world, i + 3, j + 7, k + 3, Blocks.air, 0);
		this.setBlock(world, i + 3, j + 7, k + 4, Blocks.air, 0);
		this.setBlock(world, i + 3, j + 7, k + 5, Blocks.air, 0);
		this.setBlock(world, i + 3, j + 7, k + 6, Blocks.air, 0);
		this.setBlock(world, i + 3, j + 7, k + 7, Blocks.air, 0);
		this.setBlock(world, i + 3, j + 7, k + 8, Blocks.air, 0);
		this.setBlock(world, i + 3, j + 7, k + 9, Blocks.air, 0);
		this.setBlock(world, i + 3, j + 7, k + 10, Blocks.air, 0);
		this.setBlock(world, i + 3, j + 7, k + 11, Blocks.air, 0);
		this.setBlock(world, i + 3, j + 7, k + 12, Blocks.air, 0);
		this.setBlock(world, i + 3, j + 7, k + 13, Blocks.air, 0);
		this.setBlock(world, i + 3, j + 7, k + 14, Blocks.air, 0);
		this.setBlock(world, i + 3, j + 7, k + 15, Blocks.air, 0);
		this.setBlock(world, i + 3, j + 7, k + 16, Blocks.air, 0);
		this.setBlock(world, i + 3, j + 7, k + 17, Blocks.air, 0);
		this.setBlock(world, i + 3, j + 7, k + 18, Blocks.air, 0);
		this.setBlock(world, i + 3, j + 7, k + 19, Blocks.air, 0);
		this.setBlock(world, i + 3, j + 7, k + 20, Blocks.air, 0);
		this.setBlock(world, i + 3, j + 7, k + 21, Blocks.air, 0);
		this.setBlock(world, i + 3, j + 7, k + 22, Blocks.air, 0);
		this.setBlock(world, i + 3, j + 7, k + 23, Blocks.air, 0);
		this.setBlock(world, i + 3, j + 7, k + 24, Blocks.air, 0);
		this.setBlock(world, i + 3, j + 7, k + 25, Blocks.air, 0);
		this.setBlock(world, i + 3, j + 7, k + 26, Blocks.air, 0);
		this.setBlock(world, i + 3, j + 7, k + 27, Blocks.air, 0);
		this.setBlock(world, i + 3, j + 7, k + 28, Blocks.air, 0);
		this.setBlock(world, i + 3, j + 7, k + 29, Blocks.air, 0);
		this.setBlock(world, i + 3, j + 7, k + 30, Blocks.air, 0);
		this.setBlock(world, i + 3, j + 7, k + 31, Blocks.air, 0);
		this.setBlock(world, i + 3, j + 7, k + 32, Blocks.air, 0);
		this.setBlock(world, i + 3, j + 7, k + 33, Blocks.air, 0);
		this.setBlock(world, i + 3, j + 7, k + 34, Blocks.air, 0);
		this.setBlock(world, i + 4, j + 0, k + 0, Blocks.grass, 0);
		this.setBlock(world, i + 4, j + 0, k + 1, Blocks.grass, 0);
		this.setBlock(world, i + 4, j + 0, k + 2, Blocks.grass, 0);
		this.setBlock(world, i + 4, j + 0, k + 3, Blocks.grass, 0);
		this.setBlock(world, i + 4, j + 0, k + 4, Blocks.grass, 0);
		this.setBlock(world, i + 4, j + 0, k + 5, Blocks.grass, 0);
		this.setBlock(world, i + 4, j + 0, k + 6, Blocks.grass, 0);
		this.setBlock(world, i + 4, j + 0, k + 7, Blocks.quartz_block, 0);
		this.setBlock(world, i + 4, j + 0, k + 8, Blocks.quartz_block, 0);
		this.setBlock(world, i + 4, j + 0, k + 9, Blocks.quartz_block, 0);
		this.setBlock(world, i + 4, j + 0, k + 10, Blocks.quartz_block, 0);
		this.setBlock(world, i + 4, j + 0, k + 11, Blocks.quartz_block, 0);
		this.setBlock(world, i + 4, j + 0, k + 12, Blocks.quartz_block, 0);
		this.setBlock(world, i + 4, j + 0, k + 13, Blocks.quartz_block, 0);
		this.setBlock(world, i + 4, j + 0, k + 14, Blocks.quartz_block, 0);
		this.setBlock(world, i + 4, j + 0, k + 15, Blocks.quartz_block, 0);
		this.setBlock(world, i + 4, j + 0, k + 16, Blocks.quartz_block, 0);
		this.setBlock(world, i + 4, j + 0, k + 17, Blocks.quartz_block, 0);
		this.setBlock(world, i + 4, j + 0, k + 18, Blocks.quartz_block, 0);
		this.setBlock(world, i + 4, j + 0, k + 19, Blocks.quartz_block, 0);
		this.setBlock(world, i + 4, j + 0, k + 20, Blocks.quartz_block, 0);
		this.setBlock(world, i + 4, j + 0, k + 21, Blocks.quartz_block, 0);
		this.setBlock(world, i + 4, j + 0, k + 22, Blocks.quartz_block, 0);
		this.setBlock(world, i + 4, j + 0, k + 23, Blocks.quartz_block, 0);
		this.setBlock(world, i + 4, j + 0, k + 24, Blocks.quartz_block, 0);
		this.setBlock(world, i + 4, j + 0, k + 25, Blocks.quartz_block, 0);
		this.setBlock(world, i + 4, j + 0, k + 26, Blocks.quartz_block, 0);
		this.setBlock(world, i + 4, j + 0, k + 27, Blocks.quartz_block, 0);
		this.setBlock(world, i + 4, j + 0, k + 28, Blocks.grass, 0);
		this.setBlock(world, i + 4, j + 0, k + 29, Blocks.grass, 0);
		this.setBlock(world, i + 4, j + 0, k + 30, Blocks.grass, 0);
		this.setBlock(world, i + 4, j + 0, k + 31, Blocks.grass, 0);
		this.setBlock(world, i + 4, j + 0, k + 32, Blocks.grass, 0);
		this.setBlock(world, i + 4, j + 0, k + 33, Blocks.grass, 0);
		this.setBlock(world, i + 4, j + 0, k + 34, Blocks.grass, 0);
		this.setBlock(world, i + 4, j + 1, k + 0, Blocks.air, 0);
		this.setBlock(world, i + 4, j + 1, k + 1, Blocks.air, 0);
		this.setBlock(world, i + 4, j + 1, k + 2, Blocks.air, 0);
		this.setBlock(world, i + 4, j + 1, k + 3, StarWarsMod.blockEndorBaseWall, 0);
		world.setBlockMetadataWithNotify(i + 4, j + 1, k + 3, 1, 2);
		this.setBlock(world, i + 4, j + 1, k + 4, Blocks.planks, 0);
		world.setBlockMetadataWithNotify(i + 4, j + 1, k + 4, 5, 2);
		this.setBlock(world, i + 4, j + 1, k + 5, Blocks.planks, 0);
		world.setBlockMetadataWithNotify(i + 4, j + 1, k + 5, 5, 2);
		this.setBlock(world, i + 4, j + 1, k + 6, StarWarsMod.blockEndorBaseWall, 0);
		world.setBlockMetadataWithNotify(i + 4, j + 1, k + 6, 1, 2);
		this.setBlock(world, i + 4, j + 1, k + 7, StarWarsMod.blockEndorBaseWall, 0);
		world.setBlockMetadataWithNotify(i + 4, j + 1, k + 7, 1, 2);
		this.setBlock(world, i + 4, j + 1, k + 8, Blocks.air, 0);
		this.setBlock(world, i + 4, j + 1, k + 9, Blocks.air, 0);
		this.setBlock(world, i + 4, j + 1, k + 10, Blocks.air, 0);
		this.setBlock(world, i + 4, j + 1, k + 11, StarWarsMod.blockEndorBaseWall, 0);
		world.setBlockMetadataWithNotify(i + 4, j + 1, k + 11, 1, 2);
		this.setBlock(world, i + 4, j + 1, k + 12, Blocks.air, 0);
		this.setBlock(world, i + 4, j + 1, k + 13, StarWarsMod.blockEndorBaseWall, 0);
		world.setBlockMetadataWithNotify(i + 4, j + 1, k + 13, 1, 2);
		this.setBlock(world, i + 4, j + 1, k + 14, Blocks.stained_glass_pane, 0);
		world.setBlockMetadataWithNotify(i + 4, j + 1, k + 14, 8, 2);
		this.setBlock(world, i + 4, j + 1, k + 15, Blocks.stained_glass_pane, 0);
		world.setBlockMetadataWithNotify(i + 4, j + 1, k + 15, 8, 2);
		this.setBlock(world, i + 4, j + 1, k + 16, Blocks.stained_glass_pane, 0);
		world.setBlockMetadataWithNotify(i + 4, j + 1, k + 16, 8, 2);
		this.setBlock(world, i + 4, j + 1, k + 17, Blocks.stained_glass_pane, 0);
		world.setBlockMetadataWithNotify(i + 4, j + 1, k + 17, 8, 2);
		this.setBlock(world, i + 4, j + 1, k + 18, Blocks.stained_glass_pane, 0);
		world.setBlockMetadataWithNotify(i + 4, j + 1, k + 18, 8, 2);
		this.setBlock(world, i + 4, j + 1, k + 19, Blocks.stained_glass_pane, 0);
		world.setBlockMetadataWithNotify(i + 4, j + 1, k + 19, 8, 2);
		this.setBlock(world, i + 4, j + 1, k + 20, Blocks.stained_glass_pane, 0);
		world.setBlockMetadataWithNotify(i + 4, j + 1, k + 20, 8, 2);
		this.setBlock(world, i + 4, j + 1, k + 21, StarWarsMod.blockEndorBaseWall, 0);
		world.setBlockMetadataWithNotify(i + 4, j + 1, k + 21, 1, 2);
		this.setBlock(world, i + 4, j + 1, k + 22, Blocks.air, 0);
		this.setBlock(world, i + 4, j + 1, k + 23, StarWarsMod.blockEndorBaseWall, 0);
		world.setBlockMetadataWithNotify(i + 4, j + 1, k + 23, 1, 2);
		this.setBlock(world, i + 4, j + 1, k + 24, Blocks.air, 0);
		this.setBlock(world, i + 4, j + 1, k + 25, Blocks.air, 0);
		this.setBlock(world, i + 4, j + 1, k + 26, Blocks.air, 0);
		this.setBlock(world, i + 4, j + 1, k + 27, StarWarsMod.blockEndorBaseWall, 0);
		world.setBlockMetadataWithNotify(i + 4, j + 1, k + 27, 1, 2);
		this.setBlock(world, i + 4, j + 1, k + 28, StarWarsMod.blockEndorBaseWall, 0);
		world.setBlockMetadataWithNotify(i + 4, j + 1, k + 28, 1, 2);
		this.setBlock(world, i + 4, j + 1, k + 29, Blocks.planks, 0);
		world.setBlockMetadataWithNotify(i + 4, j + 1, k + 29, 5, 2);
		this.setBlock(world, i + 4, j + 1, k + 30, Blocks.planks, 0);
		world.setBlockMetadataWithNotify(i + 4, j + 1, k + 30, 5, 2);
		this.setBlock(world, i + 4, j + 1, k + 31, StarWarsMod.blockEndorBaseWall, 0);
		world.setBlockMetadataWithNotify(i + 4, j + 1, k + 31, 1, 2);
		this.setBlock(world, i + 4, j + 1, k + 32, Blocks.air, 0);
		this.setBlock(world, i + 4, j + 1, k + 33, Blocks.air, 0);
		this.setBlock(world, i + 4, j + 1, k + 34, Blocks.air, 0);
		this.setBlock(world, i + 4, j + 2, k + 0, Blocks.air, 0);
		this.setBlock(world, i + 4, j + 2, k + 1, Blocks.air, 0);
		this.setBlock(world, i + 4, j + 2, k + 2, Blocks.air, 0);
