package com.parzivail.test;

import java.util.Random;
import net.minecraft.block.Block;
import net.minecraft.init.Blocks;
import net.minecraft.world.World;
import net.minecraft.world.chunk.IChunkProvider;
import net.minecraft.world.gen.feature.WorldGenerator;
import cpw.mods.fml.common.IWorldGenerator;
import net.minecraft.nbt.NBTTagCompound;
import com.parzivail.pswm.StarWarsMod;

public class WorldGenMysteryShrine extends WorldGenerator implements IWorldGenerator
{
	public WorldGenMysteryShrine() { }

	@Override
	public void generate(Random random, int chunkX, int chunkZ, World world, IChunkProvider chunkGenerator, IChunkProvider chunkProvider) { }

	public void setBlock(World world, int x, int y, int z, Block block, int metadata)
	{
		world.setBlock(x, y, z, block, metadata, 2);
	}

	public boolean generate(World world, Random rand, int i, int j, int k)
	{
		this.setBlock(world, i + 0, j + 0, k + 0, Blocks.air, 0);
		this.setBlock(world, i + 0, j + 0, k + 1, Blocks.air, 0);
		this.setBlock(world, i + 0, j + 0, k + 2, Blocks.air, 0);
		this.setBlock(world, i + 0, j + 0, k + 3, Blocks.air, 0);
		this.setBlock(world, i + 0, j + 0, k + 4, Blocks.air, 0);
		this.setBlock(world, i + 0, j + 0, k + 5, Blocks.air, 0);
		this.setBlock(world, i + 0, j + 0, k + 6, Blocks.air, 0);
		this.setBlock(world, i + 0, j + 0, k + 7, Blocks.air, 0);
		this.setBlock(world, i + 0, j + 1, k + 0, Blocks.air, 0);
		this.setBlock(world, i + 0, j + 1, k + 1, Blocks.air, 0);
		this.setBlock(world, i + 0, j + 1, k + 2, Blocks.air, 0);
		this.setBlock(world, i + 0, j + 1, k + 3, Blocks.air, 0);
		this.setBlock(world, i + 0, j + 1, k + 4, Blocks.air, 0);
		this.setBlock(world, i + 0, j + 1, k + 5, Blocks.air, 0);
		this.setBlock(world, i + 0, j + 1, k + 6, Blocks.air, 0);
		this.setBlock(world, i + 0, j + 1, k + 7, Blocks.air, 0);
		this.setBlock(world, i + 0, j + 2, k + 0, Blocks.stonebrick, 0);
		world.setBlockMetadataWithNotify(i + 0, j + 2, k + 0, 3, 2);
		this.setBlock(world, i + 0, j + 2, k + 1, Blocks.stonebrick, 0);
		world.setBlockMetadataWithNotify(i + 0, j + 2, k + 1, 1, 2);
		this.setBlock(world, i + 0, j + 2, k + 2, Blocks.stonebrick, 0);
		world.setBlockMetadataWithNotify(i + 0, j + 2, k + 2, 3, 2);
		this.setBlock(world, i + 0, j + 2, k + 3, Blocks.stonebrick, 0);
		world.setBlockMetadataWithNotify(i + 0, j + 2, k + 3, 2, 2);
		this.setBlock(world, i + 0, j + 2, k + 4, Blocks.stonebrick, 0);
		this.setBlock(world, i + 0, j + 2, k + 5, Blocks.stonebrick, 0);
		world.setBlockMetadataWithNotify(i + 0, j + 2, k + 5, 3, 2);
		this.setBlock(world, i + 0, j + 2, k + 6, Blocks.stonebrick, 0);
		world.setBlockMetadataWithNotify(i + 0, j + 2, k + 6, 1, 2);
		this.setBlock(world, i + 0, j + 2, k + 7, Blocks.stonebrick, 0);
		world.setBlockMetadataWithNotify(i + 0, j + 2, k + 7, 3, 2);
		this.setBlock(world, i + 0, j + 3, k + 0, Blocks.torch, 0);
		world.setBlockMetadataWithNotify(i + 0, j + 3, k + 0, 5, 2);
		this.setBlock(world, i + 0, j + 3, k + 1, Blocks.air, 0);
		this.setBlock(world, i + 0, j + 3, k + 2, Blocks.air, 0);
		this.setBlock(world, i + 0, j + 3, k + 3, Blocks.air, 0);
		this.setBlock(world, i + 0, j + 3, k + 4, Blocks.air, 0);
		this.setBlock(world, i + 0, j + 3, k + 5, Blocks.air, 0);
		this.setBlock(world, i + 0, j + 3, k + 6, Blocks.air, 0);
		this.setBlock(world, i + 0, j + 3, k + 7, Blocks.torch, 0);
		world.setBlockMetadataWithNotify(i + 0, j + 3, k + 7, 5, 2);
		this.setBlock(world, i + 1, j + 0, k + 0, Blocks.air, 0);
		this.setBlock(world, i + 1, j + 0, k + 1, Blocks.air, 0);
		this.setBlock(world, i + 1, j + 0, k + 2, Blocks.air, 0);
		this.setBlock(world, i + 1, j + 0, k + 3, Blocks.air, 0);
		this.setBlock(world, i + 1, j + 0, k + 4, Blocks.air, 0);
		this.setBlock(world, i + 1, j + 0, k + 5, Blocks.air, 0);
		this.setBlock(world, i + 1, j + 0, k + 6, Blocks.air, 0);
		this.setBlock(world, i + 1, j + 0, k + 7, Blocks.air, 0);
		this.setBlock(world, i + 1, j + 1, k + 0, Blocks.air, 0);
		this.setBlock(world, i + 1, j + 1, k + 1, Blocks.air, 0);
		this.setBlock(world, i + 1, j + 1, k + 2, Blocks.stonebrick, 0);
		this.setBlock(world, i + 1, j + 1, k + 3, Blocks.stonebrick, 0);
		this.setBlock(world, i + 1, j + 1, k + 4, Blocks.stonebrick, 0);
		world.setBlockMetadataWithNotify(i + 1, j + 1, k + 4, 1, 2);
		this.setBlock(world, i + 1, j + 1, k + 5, Blocks.stonebrick, 0);
		world.setBlockMetadataWithNotify(i + 1, j + 1, k + 5, 1, 2);
		this.setBlock(world, i + 1, j + 1, k + 6, Blocks.air, 0);
		this.setBlock(world, i + 1, j + 1, k + 7, Blocks.air, 0);
		this.setBlock(world, i + 1, j + 2, k + 0, Blocks.stonebrick, 0);
		this.setBlock(world, i + 1, j + 2, k + 1, Blocks.stonebrick, 0);
		world.setBlockMetadataWithNotify(i + 1, j + 2, k + 1, 3, 2);
		this.setBlock(world, i + 1, j + 2, k + 2, Blocks.stone_brick_stairs, 0);
		world.setBlockMetadataWithNotify(i + 1, j + 2, k + 2, 1, 2);
		this.setBlock(world, i + 1, j + 2, k + 3, Blocks.stone_brick_stairs, 0);
		world.setBlockMetadataWithNotify(i + 1, j + 2, k + 3, 1, 2);
		this.setBlock(world, i + 1, j + 2, k + 4, Blocks.stone_brick_stairs, 0);
		world.setBlockMetadataWithNotify(i + 1, j + 2, k + 4, 1, 2);
		this.setBlock(world, i + 1, j + 2, k + 5, Blocks.stone_brick_stairs, 0);
		world.setBlockMetadataWithNotify(i + 1, j + 2, k + 5, 1, 2);
		this.setBlock(world, i + 1, j + 2, k + 6, Blocks.stonebrick, 0);
		world.setBlockMetadataWithNotify(i + 1, j + 2, k + 6, 3, 2);
		this.setBlock(world, i + 1, j + 2, k + 7, Blocks.stonebrick, 0);
		world.setBlockMetadataWithNotify(i + 1, j + 2, k + 7, 2, 2);
		this.setBlock(world, i + 1, j + 3, k + 0, Blocks.air, 0);
		this.setBlock(world, i + 1, j + 3, k + 1, Blocks.air, 0);
		this.setBlock(world, i + 1, j + 3, k + 2, Blocks.air, 0);
		this.setBlock(world, i + 1, j + 3, k + 3, Blocks.air, 0);
		this.setBlock(world, i + 1, j + 3, k + 4, Blocks.air, 0);
		this.setBlock(world, i + 1, j + 3, k + 5, Blocks.air, 0);
		this.setBlock(world, i + 1, j + 3, k + 6, Blocks.air, 0);
		this.setBlock(world, i + 1, j + 3, k + 7, Blocks.air, 0);
		this.setBlock(world, i + 2, j + 0, k + 0, Blocks.air, 0);
		this.setBlock(world, i + 2, j + 0, k + 1, Blocks.air, 0);
		this.setBlock(world, i + 2, j + 0, k + 2, Blocks.stonebrick, 0);
		this.setBlock(world, i + 2, j + 0, k + 3, Blocks.stonebrick, 0);
		this.setBlock(world, i + 2, j + 0, k + 4, Blocks.stonebrick, 0);
		this.setBlock(world, i + 2, j + 0, k + 5, Blocks.stonebrick, 0);
		this.setBlock(world, i + 2, j + 0, k + 6, Blocks.air, 0);
		this.setBlock(world, i + 2, j + 0, k + 7, Blocks.air, 0);
		this.setBlock(world, i + 2, j + 1, k + 0, Blocks.air, 0);
		this.setBlock(world, i + 2, j + 1, k + 1, Blocks.stonebrick, 0);
		world.setBlockMetadataWithNotify(i + 2, j + 1, k + 1, 1, 2);
		this.setBlock(world, i + 2, j + 1, k + 2, Blocks.cobblestone_wall, 0);
		this.setBlock(world, i + 2, j + 1, k + 3, Blocks.cobblestone_wall, 0);
		world.setBlockMetadataWithNotify(i + 2, j + 1, k + 3, 1, 2);
		this.setBlock(world, i + 2, j + 1, k + 4, Blocks.cobblestone_wall, 0);
		this.setBlock(world, i + 2, j + 1, k + 5, Blocks.cobblestone_wall, 0);
		this.setBlock(world, i + 2, j + 1, k + 6, Blocks.stonebrick, 0);
		this.setBlock(world, i + 2, j + 1, k + 7, Blocks.air, 0);
		this.setBlock(world, i + 2, j + 2, k + 0, Blocks.stonebrick, 0);
		world.setBlockMetadataWithNotify(i + 2, j + 2, k + 0, 1, 2);
		this.setBlock(world, i + 2, j + 2, k + 1, Blocks.stone_brick_stairs, 0);
		world.setBlockMetadataWithNotify(i + 2, j + 2, k + 1, 3, 2);
		this.setBlock(world, i + 2, j + 2, k + 2, Blocks.torch, 0);
		world.setBlockMetadataWithNotify(i + 2, j + 2, k + 2, 5, 2);
		this.setBlock(world, i + 2, j + 2, k + 3, Blocks.air, 0);
		this.setBlock(world, i + 2, j + 2, k + 4, Blocks.air, 0);
		this.setBlock(world, i + 2, j + 2, k + 5, Blocks.torch, 0);
		world.setBlockMetadataWithNotify(i + 2, j + 2, k + 5, 5, 2);
		this.setBlock(world, i + 2, j + 2, k + 6, Blocks.stone_brick_stairs, 0);
		world.setBlockMetadataWithNotify(i + 2, j + 2, k + 6, 2, 2);
		this.setBlock(world, i + 2, j + 2, k + 7, Blocks.stonebrick, 0);
		this.setBlock(world, i + 2, j + 3, k + 0, Blocks.air, 0);
		this.setBlock(world, i + 2, j + 3, k + 1, Blocks.air, 0);
		this.setBlock(world, i + 2, j + 3, k + 2, Blocks.air, 0);
		this.setBlock(world, i + 2, j + 3, k + 3, Blocks.air, 0);
		this.setBlock(world, i + 2, j + 3, k + 4, Blocks.air, 0);
		this.setBlock(world, i + 2, j + 3, k + 5, Blocks.air, 0);
		this.setBlock(world, i + 2, j + 3, k + 6, Blocks.air, 0);
		this.setBlock(world, i + 2, j + 3, k + 7, Blocks.air, 0);
		this.setBlock(world, i + 3, j + 0, k + 0, Blocks.air, 0);
		this.setBlock(world, i + 3, j + 0, k + 1, Blocks.air, 0);
		this.setBlock(world, i + 3, j + 0, k + 2, Blocks.stonebrick, 0);
		this.setBlock(world, i + 3, j + 0, k + 3, Blocks.stonebrick, 0);
		world.setBlockMetadataWithNotify(i + 3, j + 0, k + 3, 3, 2);
		this.setBlock(world, i + 3, j + 0, k + 4, Blocks.stonebrick, 0);
		world.setBlockMetadataWithNotify(i + 3, j + 0, k + 4, 3, 2);
		this.setBlock(world, i + 3, j + 0, k + 5, Blocks.stonebrick, 0);
		this.setBlock(world, i + 3, j + 0, k + 6, Blocks.air, 0);
		this.setBlock(world, i + 3, j + 0, k + 7, Blocks.air, 0);
		this.setBlock(world, i + 3, j + 1, k + 0, Blocks.air, 0);
		this.setBlock(world, i + 3, j + 1, k + 1, Blocks.stonebrick, 0);
		this.setBlock(world, i + 3, j + 1, k + 2, Blocks.cobblestone_wall, 0);
		world.setBlockMetadataWithNotify(i + 3, j + 1, k + 2, 1, 2);
		this.setBlock(world, i + 3, j + 1, k + 3, Blocks.chest, 0);
		world.setBlockMetadataWithNotify(i + 3, j + 1, k + 3, 4, 2);
		this.setBlock(world, i + 3, j + 1, k + 4, Blocks.chest, 0);
		world.setBlockMetadataWithNotify(i + 3, j + 1, k + 4, 4, 2);
		this.setBlock(world, i + 3, j + 1, k + 5, Blocks.cobblestone_wall, 0);
		this.setBlock(world, i + 3, j + 1, k + 6, Blocks.stonebrick, 0);
		this.setBlock(world, i + 3, j + 1, k + 7, Blocks.air, 0);
		this.setBlock(world, i + 3, j + 2, k + 0, Blocks.stonebrick, 0);
		world.setBlockMetadataWithNotify(i + 3, j + 2, k + 0, 3, 2);
		this.setBlock(world, i + 3, j + 2, k + 1, Blocks.stone_brick_stairs, 0);
		world.setBlockMetadataWithNotify(i + 3, j + 2, k + 1, 3, 2);
		this.setBlock(world, i + 3, j + 2, k + 2, Blocks.air, 0);
		this.setBlock(world, i + 3, j + 2, k + 3, Blocks.air, 0);
		this.setBlock(world, i + 3, j + 2, k + 4, Blocks.air, 0);
		this.setBlock(world, i + 3, j + 2, k + 5, Blocks.air, 0);
		this.setBlock(world, i + 3, j + 2, k + 6, Blocks.stone_brick_stairs, 0);
		world.setBlockMetadataWithNotify(i + 3, j + 2, k + 6, 2, 2);
		this.setBlock(world, i + 3, j + 2, k + 7, Blocks.stonebrick, 0);
		world.setBlockMetadataWithNotify(i + 3, j + 2, k + 7, 3, 2);
		this.setBlock(world, i + 3, j + 3, k + 0, Blocks.air, 0);
		this.setBlock(world, i + 3, j + 3, k + 1, Blocks.air, 0);
		this.setBlock(world, i + 3, j + 3, k + 2, Blocks.air, 0);
		this.setBlock(world, i + 3, j + 3, k + 3, Blocks.air, 0);
		this.setBlock(world, i + 3, j + 3, k + 4, Blocks.air, 0);
		this.setBlock(world, i + 3, j + 3, k + 5, Blocks.air, 0);
		this.setBlock(world, i + 3, j + 3, k + 6, Blocks.air, 0);
		this.setBlock(world, i + 3, j + 3, k + 7, Blocks.air, 0);
		this.setBlock(world, i + 4, j + 0, k + 0, Blocks.air, 0);
		this.setBlock(world, i + 4, j + 0, k + 1, Blocks.air, 0);
		this.setBlock(world, i + 4, j + 0, k + 2, Blocks.stonebrick, 0);
		this.setBlock(world, i + 4, j + 0, k + 3, Blocks.stonebrick, 0);
		this.setBlock(world, i + 4, j + 0, k + 4, Blocks.stonebrick, 0);
		this.setBlock(world, i + 4, j + 0, k + 5, Blocks.stonebrick, 0);
		this.setBlock(world, i + 4, j + 0, k + 6, Blocks.air, 0);
		this.setBlock(world, i + 4, j + 0, k + 7, Blocks.air, 0);
		this.setBlock(world, i + 4, j + 1, k + 0, Blocks.air, 0);
		this.setBlock(world, i + 4, j + 1, k + 1, Blocks.stonebrick, 0);
		world.setBlockMetadataWithNotify(i + 4, j + 1, k + 1, 1, 2);
		this.setBlock(world, i + 4, j + 1, k + 2, Blocks.cobblestone_wall, 0);
		this.setBlock(world, i + 4, j + 1, k + 3, Blocks.cobblestone_wall, 0);
		world.setBlockMetadataWithNotify(i + 4, j + 1, k + 3, 1, 2);
		this.setBlock(world, i + 4, j + 1, k + 4, Blocks.cobblestone_wall, 0);
		this.setBlock(world, i + 4, j + 1, k + 5, Blocks.cobblestone_wall, 0);
		world.setBlockMetadataWithNotify(i + 4, j + 1, k + 5, 1, 2);
		this.setBlock(world, i + 4, j + 1, k + 6, Blocks.stonebrick, 0);
		world.setBlockMetadataWithNotify(i + 4, j + 1, k + 6, 1, 2);
		this.setBlock(world, i + 4, j + 1, k + 7, Blocks.air, 0);
		this.setBlock(world, i + 4, j + 2, k + 0, Blocks.stonebrick, 0);
		world.setBlockMetadataWithNotify(i + 4, j + 2, k + 0, 2, 2);
		this.setBlock(world, i + 4, j + 2, k + 1, Blocks.stone_brick_stairs, 0);
		world.setBlockMetadataWithNotify(i + 4, j + 2, k + 1, 3, 2);
		this.setBlock(world, i + 4, j + 2, k + 2, Blocks.torch, 0);
		world.setBlockMetadataWithNotify(i + 4, j + 2, k + 2, 5, 2);
		this.setBlock(world, i + 4, j + 2, k + 3, Blocks.air, 0);
		this.setBlock(world, i + 4, j + 2, k + 4, Blocks.air, 0);
		this.setBlock(world, i + 4, j + 2, k + 5, Blocks.torch, 0);
		world.setBlockMetadataWithNotify(i + 4, j + 2, k + 5, 5, 2);
		this.setBlock(world, i + 4, j + 2, k + 6, Blocks.stone_brick_stairs, 0);
		world.setBlockMetadataWithNotify(i + 4, j + 2, k + 6, 2, 2);
		this.setBlock(world, i + 4, j + 2, k + 7, Blocks.stonebrick, 0);
		this.setBlock(world, i + 4, j + 3, k + 0, Blocks.air, 0);
		this.setBlock(world, i + 4, j + 3, k + 1, Blocks.air, 0);
		this.setBlock(world, i + 4, j + 3, k + 2, Blocks.air, 0);
		this.setBlock(world, i + 4, j + 3, k + 3, Blocks.air, 0);
		this.setBlock(world, i + 4, j + 3, k + 4, Blocks.air, 0);
		this.setBlock(world, i + 4, j + 3, k + 5, Blocks.air, 0);
		this.setBlock(world, i + 4, j + 3, k + 6, Blocks.air, 0);
		this.setBlock(world, i + 4, j + 3, k + 7, Blocks.air, 0);
		this.setBlock(world, i + 5, j + 0, k + 0, Blocks.air, 0);
		this.setBlock(world, i + 5, j + 0, k + 1, Blocks.air, 0);
		this.setBlock(world, i + 5, j + 0, k + 2, Blocks.air, 0);
		this.setBlock(world, i + 5, j + 0, k + 3, Blocks.air, 0);
		this.setBlock(world, i + 5, j + 0, k + 4, Blocks.air, 0);
		this.setBlock(world, i + 5, j + 0, k + 5, Blocks.air, 0);
		this.setBlock(world, i + 5, j + 0, k + 6, Blocks.air, 0);
		this.setBlock(world, i + 5, j + 0, k + 7, Blocks.air, 0);
		this.setBlock(world, i + 5, j + 1, k + 0, Blocks.air, 0);
		this.setBlock(world, i + 5, j + 1, k + 1, Blocks.air, 0);
		this.setBlock(world, i + 5, j + 1, k + 2, Blocks.stonebrick, 0);
		world.setBlockMetadataWithNotify(i + 5, j + 1, k + 2, 1, 2);
		this.setBlock(world, i + 5, j + 1, k + 3, Blocks.stonebrick, 0);
		this.setBlock(world, i + 5, j + 1, k + 4, Blocks.stonebrick, 0);
		world.setBlockMetadataWithNotify(i + 5, j + 1, k + 4, 1, 2);
		this.setBlock(world, i + 5, j + 1, k + 5, Blocks.stonebrick, 0);
		this.setBlock(world, i + 5, j + 1, k + 6, Blocks.air, 0);
		this.setBlock(world, i + 5, j + 1, k + 7, Blocks.air, 0);
		this.setBlock(world, i + 5, j + 2, k + 0, Blocks.stonebrick, 0);
		this.setBlock(world, i + 5, j + 2, k + 1, Blocks.stonebrick, 0);
		world.setBlockMetadataWithNotify(i + 5, j + 2, k + 1, 3, 2);
		this.setBlock(world, i + 5, j + 2, k + 2, Blocks.stone_brick_stairs, 0);
		this.setBlock(world, i + 5, j + 2, k + 3, Blocks.stone_brick_stairs, 0);
		this.setBlock(world, i + 5, j + 2, k + 4, Blocks.stone_brick_stairs, 0);
		this.setBlock(world, i + 5, j + 2, k + 5, Blocks.stone_brick_stairs, 0);
		this.setBlock(world, i + 5, j + 2, k + 6, Blocks.stonebrick, 0);
		world.setBlockMetadataWithNotify(i + 5, j + 2, k + 6, 3, 2);
		this.setBlock(world, i + 5, j + 2, k + 7, Blocks.stonebrick, 0);
		world.setBlockMetadataWithNotify(i + 5, j + 2, k + 7, 1, 2);
		this.setBlock(world, i + 5, j + 3, k + 0, Blocks.air, 0);
		this.setBlock(world, i + 5, j + 3, k + 1, Blocks.air, 0);
		this.setBlock(world, i + 5, j + 3, k + 2, Blocks.air, 0);
		this.setBlock(world, i + 5, j + 3, k + 3, Blocks.air, 0);
		this.setBlock(world, i + 5, j + 3, k + 4, Blocks.air, 0);
		this.setBlock(world, i + 5, j + 3, k + 5, Blocks.air, 0);
		this.setBlock(world, i + 5, j + 3, k + 6, Blocks.air, 0);
		this.setBlock(world, i + 5, j + 3, k + 7, Blocks.air, 0);
		this.setBlock(world, i + 6, j + 0, k + 0, Blocks.air, 0);
		this.setBlock(world, i + 6, j + 0, k + 1, Blocks.air, 0);
		this.setBlock(world, i + 6, j + 0, k + 2, Blocks.air, 0);
		this.setBlock(world, i + 6, j + 0, k + 3, Blocks.air, 0);
		this.setBlock(world, i + 6, j + 0, k + 4, Blocks.air, 0);
		this.setBlock(world, i + 6, j + 0, k + 5, Blocks.air, 0);
		this.setBlock(world, i + 6, j + 0, k + 6, Blocks.air, 0);
		this.setBlock(world, i + 6, j + 0, k + 7, Blocks.air, 0);
		this.setBlock(world, i + 6, j + 1, k + 0, Blocks.air, 0);
		this.setBlock(world, i + 6, j + 1, k + 1, Blocks.air, 0);
		this.setBlock(world, i + 6, j + 1, k + 2, Blocks.air, 0);
		this.setBlock(world, i + 6, j + 1, k + 3, Blocks.air, 0);
		this.setBlock(world, i + 6, j + 1, k + 4, Blocks.air, 0);
		this.setBlock(world, i + 6, j + 1, k + 5, Blocks.air, 0);
		this.setBlock(world, i + 6, j + 1, k + 6, Blocks.air, 0);
		this.setBlock(world, i + 6, j + 1, k + 7, Blocks.air, 0);
		this.setBlock(world, i + 6, j + 2, k + 0, Blocks.stonebrick, 0);
		world.setBlockMetadataWithNotify(i + 6, j + 2, k + 0, 3, 2);
		this.setBlock(world, i + 6, j + 2, k + 1, Blocks.stonebrick, 0);
		world.setBlockMetadataWithNotify(i + 6, j + 2, k + 1, 1, 2);
		this.setBlock(world, i + 6, j + 2, k + 2, Blocks.stonebrick, 0);
		world.setBlockMetadataWithNotify(i + 6, j + 2, k + 2, 3, 2);
		this.setBlock(world, i + 6, j + 2, k + 3, Blocks.stonebrick, 0);
		world.setBlockMetadataWithNotify(i + 6, j + 2, k + 3, 2, 2);
		this.setBlock(world, i + 6, j + 2, k + 4, Blocks.stonebrick, 0);
		this.setBlock(world, i + 6, j + 2, k + 5, Blocks.stonebrick, 0);
		world.setBlockMetadataWithNotify(i + 6, j + 2, k + 5, 3, 2);
		this.setBlock(world, i + 6, j + 2, k + 6, Blocks.stonebrick, 0);
		this.setBlock(world, i + 6, j + 2, k + 7, Blocks.stonebrick, 0);
		world.setBlockMetadataWithNotify(i + 6, j + 2, k + 7, 3, 2);
		this.setBlock(world, i + 6, j + 3, k + 0, Blocks.torch, 0);
		world.setBlockMetadataWithNotify(i + 6, j + 3, k + 0, 5, 2);
		this.setBlock(world, i + 6, j + 3, k + 1, Blocks.air, 0);
		this.setBlock(world, i + 6, j + 3, k + 2, Blocks.air, 0);
		this.setBlock(world, i + 6, j + 3, k + 3, Blocks.air, 0);
		this.setBlock(world, i + 6, j + 3, k + 4, Blocks.air, 0);
		this.setBlock(world, i + 6, j + 3, k + 5, Blocks.air, 0);
		this.setBlock(world, i + 6, j + 3, k + 6, Blocks.air, 0);
		this.setBlock(world, i + 6, j + 3, k + 7, Blocks.torch, 0);
		world.setBlockMetadataWithNotify(i + 6, j + 3, k + 7, 5, 2);
		NBTTagCompound tag0 = new NBTTagCompound();
		tag0.setString("id", "Chest");
		tag0.setInteger("x", 3);
		tag0.setInteger("y", 1);
		tag0.setInteger("z", 4);
		world.getTileEntity(i + 3, j + 1, k + 4).readFromNBT(tag0);

		NBTTagCompound tag1 = new NBTTagCompound();
		tag1.setString("id", "Chest");
		tag1.setInteger("x", 3);
		tag1.setInteger("y", 1);
		tag1.setInteger("z", 3);
		world.getTileEntity(i + 3, j + 1, k + 3).readFromNBT(tag1);

		return true;
	}

}
